<robot name="dyros_tocabi_description">
    <link name="Pelvis_Virtual_Link" />
    <link name="Pelvis_Link">
        <inertial>
            <origin xyz="0.07809 0 0.03985" rpy="0 0 0" />
            <mass value="12.19525" />
            <inertia ixx="0.101833182" ixy="-0.000070812" ixz="-0.003831096" iyy="0.072400662" iyz="0.000079272" izz="0.144478157" />
        </inertial>
        <visual>
            <origin xyz="0.11 0 0.02" rpy="0 0 0" />
            <geometry>
                <mesh filename="package://tocabi_description/meshes/Pelvis_link.STL" />
            </geometry>
            <material name="">
                <color rgba="0.79216 0.81961 0.93333 1" />
            </material>
        </visual>
        <collision>
            <origin xyz="0.11 0 0.039" rpy="0 0 0" />
            <geometry>
                <cylinder length="0.088" radius="0.045" />
            </geometry>
        </collision>
        <collision>
            <origin xyz="0.11 0.1025 0.05" rpy="0 0 0" />
            <geometry>
                <cylinder length="0.11" radius="0.045" />
            </geometry>
        </collision>
        <collision>
            <origin xyz="0.11 -0.1025 0.05" rpy="0 0 0" />
            <geometry>
                <cylinder length="0.11" radius="0.045" />
            </geometry>
        </collision>
        <collision>
            <origin xyz="-0.0895 0 0.02" rpy="0 0 0" />
            <geometry>
                <box size="0.141 0.305 0.05" />
            </geometry>
        </collision>
    </link>
    <joint name="Pelvis_Virtual_Joint" type="fixed">
        <parent link="Pelvis_Virtual_Link" />
        <child link="Pelvis_Link" />
    </joint>
    <link name="R_HipRoll_Link">
        <inertial>
            <origin xyz="-0.06477 0 0.05149" rpy="0 0 0" />
            <mass value="2.679" />
            <inertia ixx="0.01821" ixy="-1.676E-07" ixz="-0.0007745" iyy="0.03121" iyz="-4.53E-09" izz="0.2928" />
        </inertial>
        <visual>
            <origin xyz="0 0 0" rpy="0 0 0" />
            <geometry>
                <mesh filename="package://tocabi_description/meshes/HipRoll_R_link.STL" />
            </geometry>
            <material name="">
                <color rgba="0.79216 0.81961 0.93333 1" />
            </material>
        </visual>
        <collision>
            <origin xyz="-0.1 0 0" rpy="0 1.570796 0" />
            <geometry>
                <cylinder length="0.08" radius="0.045" />
            </geometry>
        </collision>
        <collision>
            <origin xyz="-0.016 0 0.085" rpy="0 0 0" />
            <geometry>
                <box size="0.154 0.1 0.02" />
            </geometry>
        </collision>
        <collision>
            <origin xyz="0.055 0 0.0475" rpy="0 0 0" />
            <geometry>
                <box size="0.012 0.072 0.095" />
            </geometry>
        </collision>
        <collision>
            <origin xyz="-0.087 0 0.0475" rpy="0 0 0" />
            <geometry>
                <box size="0.012 0.072 0.095" />
            </geometry>
        </collision>
    </link>
    <joint name="R_HipYaw_Joint" type="revolute">
        <origin xyz="0.11 -0.1025 -0.1025" rpy="0 0 0" />
        <parent link="Pelvis_Link" />
        <child link="R_HipRoll_Link" />
        <axis xyz="0 0 1" />
        <limit lower="-3.14" upper="3.14" effort="500" velocity="100" />
        <dynamics damping="5" />
    </joint>
    <link name="R_HipCenter_Link">
        <inertial>
            <origin xyz="-0.04801 -0.0022 2E-05" rpy="0 0 0" />
            <mass value="2.67" />
            <inertia ixx="0.3553" ixy="1.725E-08" ixz="-3.236E-06" iyy="0.009161" iyz="-4.778E-06" izz="0.00876" />
        </inertial>
        <visual>
            <origin xyz="0 0 0" rpy="0 0 0" />
            <geometry>
                <mesh filename="package://tocabi_description/meshes/HipCenter_R_Link.STL" />
            </geometry>
            <material name="">
                <color rgba="0.79216 0.81961 0.93333 1" />
            </material>
        </visual>
        <collision>
            <origin xyz="-0.0045 0 0" rpy="0 0 0" />
            <geometry>
                <box size="0.1045 0.06 0.095" />
            </geometry>
        </collision>
    </link>
    <joint name="R_HipRoll_Joint" type="revolute">
        <origin xyz="0 0 0" rpy="1.38777878078145E-17 2.74984739744835E-16 4.49346870585602E-16" />
        <parent link="R_HipRoll_Link" />
        <child link="R_HipCenter_Link" />
        <axis xyz="1 0 0" />
        <limit lower="-3.14" upper="3.14" effort="500" velocity="100" />
        <dynamics damping="5" />
    </joint>
    <link name="R_Thigh_Link">
        <inertial>
            <origin xyz="-0.00042 -0.00032 -0.18904" rpy="0 0 0" />
            <mass value="5.366" />
            <inertia ixx="0.2987" ixy="-4.284E-05" ixz="-0.000196" iyy="0.7088" iyz="0.002406" izz="0.00982" />
        </inertial>
        <visual>
            <origin xyz="0 0 0" rpy="0 0 0" />
            <geometry>
                <mesh filename="package://tocabi_description/meshes/Thigh_R_Link.STL" />
            </geometry>
            <material name="">
                <color rgba="0.79216 0.81961 0.93333 1" />
            </material>
        </visual>
        <collision>
            <origin xyz="0 0 -0.35" rpy="1.570796 0 0" />
            <geometry>
                <cylinder length="0.07763" radius="0.049" />
            </geometry>
        </collision>
        <collision>
            <origin xyz="0 0 -0.1923" rpy="0 0 0" />
            <geometry>
                <cylinder length="0.2175" radius="0.06" />
            </geometry>
        </collision>
    </link>
    <joint name="R_HipPitch_Joint" type="revolute">
        <origin xyz="0 0 0" rpy="-1.38777878078143E-17 -2.74984739744835E-16 -4.49346870585602E-16" />
        <parent link="R_HipCenter_Link" />
        <child link="R_Thigh_Link" />
        <axis xyz="0 1 0" />
        <limit lower="-3.14" upper="3.14" effort="500" velocity="100" />
        <dynamics damping="5" />
    </joint>
    <link name="R_Knee_Link">
        <inertial>
            <origin xyz="0.00429 0.00214 -0.1428" rpy="0 0 0" />
            <mass value="3.883" />
            <inertia ixx="0.1506" ixy="-2.887E-05" ixz="-0.002607" iyy="0.5588" iyz="-0.001486" izz="0.007451" />
        </inertial>
        <visual>
            <origin xyz="0 0 0" rpy="0 0 0" />
            <geometry>
                <mesh filename="package://tocabi_description/meshes/Knee_R_Link.STL" />
            </geometry>
            <material name="">
                <color rgba="0.79216 0.81961 0.93333 1" />
            </material>
        </visual>
        <collision>
            <origin xyz="0 0 -0.175" rpy="0 0 0" />
            <geometry>
                <cylinder length="0.200" radius="0.06" />
            </geometry>
        </collision>
    </link>
    <joint name="R_Knee_Joint" type="revolute">
        <origin xyz="0 0 -0.349999999999809" rpy="0 0 0" />
        <parent link="R_Thigh_Link" />
        <child link="R_Knee_Link" />
        <axis xyz="0 1 0" />
        <limit lower="-3.14" upper="3.14" effort="500" velocity="100" />
        <dynamics damping="5" />
    </joint>
    <link name="R_AnkleCenter_Link">
        <inertial>
            <origin xyz="-0.00419 -0.0018 -0.0003" rpy="0 0 0" />
            <mass value="2.51" />
            <inertia ixx="0.002857" ixy="-1.422E-07" ixz="2.222E-06" iyy="0.4135" iyz="4.611E-06" izz="0.003345" />
        </inertial>
        <visual>
            <origin xyz="0 0 0" rpy="0 0 0" />
            <geometry>
                <mesh filename="package://tocabi_description/meshes/AnkleCenter_R_Link.STL" />
            </geometry>
            <material name="">
                <color rgba="0.79216 0.81961 0.93333 1" />
            </material>
        </visual>
        <collision>
            <origin xyz="-0.0045 0 0" rpy="0 0 0" />
            <geometry>
                <box size="0.1045 0.06 0.095" />
            </geometry>
        </collision>
    </link>
    <joint name="R_AnklePitch_Joint" type="revolute">
        <origin xyz="0 0 -0.35" rpy="-2.77555756156282E-17 -1.48042453629419E-16 5.37756273475549E-16" />
        <parent link="R_Knee_Link" />
        <child link="R_AnkleCenter_Link" />
        <axis xyz="0 1 0" />
        <limit lower="-3.14" upper="3.14" effort="500" velocity="100" />
        <dynamics damping="5" />
    </joint>
    <link name="R_AnkleRoll_Link">
        <inertial>
            <origin xyz="-0.05196 0.00005 -0.0219" rpy="0 0 0" />
            <mass value="1.26426" />
            <inertia ixx="0.418697" ixy="1.5176E-08" ixz="-0.001095976" iyy="0.006211405" iyz="-5.435E-08" izz="0.008575514" />
        </inertial>
        <visual>
            <origin xyz="0 0 0" rpy="0 0 0" />
            <geometry>
                <mesh filename="package://tocabi_description/meshes/AnkleRoll_R_Link.STL" />
            </geometry>
            <material name="">
                <color rgba="0.79216 0.81961 0.93333 1" />
            </material>
        </visual>
        <collision>
            <origin xyz="-0.08875 0 0" rpy="0 -1.5707963 0" />
            <geometry>
                <cylinder length="0.0625" radius="0.045" />
            </geometry>
        </collision>
    </link>
    <joint name="R_AnkleRoll_Joint" type="revolute">
        <origin xyz="0 0 0" rpy="0 0 0" />
        <parent link="R_AnkleCenter_Link" />
        <child link="R_AnkleRoll_Link" />
        <axis xyz="1 0 0" />
        <limit lower="-3.14" upper="3.14" effort="500" velocity="100" />
        <dynamics damping="5" />
    </joint>
    <link name="R_Foot_Link">
        <inertial>
            <origin xyz="0.0162 0.00008 -0.1209" rpy="0 0 0" />
            <mass value="2.326" />
            <inertia ixx="0.003386409" ixy="1.1237E-05" ixz="-0.000526477" iyy="0.012600125" iyz="-1.976E-06" izz="0.014296" />
        </inertial>
        <visual>
            <origin xyz="0 0 0" rpy="0 0 0" />
            <geometry>
                <mesh filename="package://tocabi_description/meshes/Foot_Link.STL" />
            </geometry>
            <material name="">
                <color rgba="0.79216 0.81961 0.93333 1" />
            </material>
        </visual>
        <collision>
            <origin xyz="0.03 0 -0.145" rpy="0 0 0" />
            <geometry>
                <box size="0.3 0.17 0.027" />
            </geometry>
        </collision>
        <collision>
            <origin xyz="-0.08875 0 0" rpy="0 -1.5707963 0" />
            <geometry>
                <cylinder length="0.0625" radius="0.045" />
            </geometry>
        </collision>
    </link>
    <joint name="R_Foot_Joint" type="fixed">
        <origin xyz="0 0 0" rpy="0 0 0" />
        <parent link="R_AnkleRoll_Link" />
        <child link="R_Foot_Link" />
        <axis xyz="0 0 0" />
        <limit lower="-3.14" upper="3.14" effort="500" velocity="100" />
        <dynamics damping="5" />
    </joint>
    <link name="L_HipRoll_Link">
        <inertial>
            <origin xyz="-0.06477 0 0.05149" rpy="0 0 0" />
            <mass value="2.679" />
            <inertia ixx="0.01821" ixy="-1.676E-07" ixz="-0.0007745" iyy="0.03121" iyz="-4.53E-09" izz="0.2928" />
        </inertial>
        <visual>
            <origin xyz="0 0 0" rpy="0 0 0" />
            <geometry>
                <mesh filename="package://tocabi_description/meshes/HipRoll_L_Link.STL" />
            </geometry>
            <material name="">
                <color rgba="0.79216 0.81961 0.93333 1" />
            </material>
        </visual>
        <collision>
            <origin xyz="-0.1 0 0" rpy="0 1.570796 0" />
            <geometry>
                <cylinder length="0.08" radius="0.045" />
            </geometry>
        </collision>
        <collision>
            <origin xyz="-0.016 0 0.085" rpy="0 0 0" />
            <geometry>
                <box size="0.154 0.1 0.02" />
            </geometry>
        </collision>
        <collision>
            <origin xyz="0.055 0 0.0475" rpy="0 0 0" />
            <geometry>
                <box size="0.012 0.072 0.095" />
            </geometry>
        </collision>
        <collision>
            <origin xyz="-0.087 0 0.0475" rpy="0 0 0" />
            <geometry>
                <box size="0.012 0.072 0.095" />
            </geometry>
        </collision>
    </link>
    <joint name="L_HipYaw_Joint" type="revolute">
        <origin xyz="0.11 0.1025 -0.1025" rpy="0 0 0" />
        <parent link="Pelvis_Link" />
        <child link="L_HipRoll_Link" />
        <axis xyz="0 0 1" />
        <limit lower="-3.14" upper="3.14" effort="500" velocity="100" />
        <dynamics damping="5" />
    </joint>
    <link name="L_HipCenter_Link">
        <inertial>
            <origin xyz="-0.04801 0.0022 2E-05" rpy="0 0 0" />
            <mass value="2.67" />
            <inertia ixx="0.3553" ixy="1.725E-08" ixz="-3.236E-06" iyy="0.009161" iyz="-4.778E-06" izz="0.00876" />
        </inertial>
        <visual>
            <origin xyz="0 0 0" rpy="0 0 0" />
            <geometry>
                <mesh filename="package://tocabi_description/meshes/HipCenter_L_Link.STL" />
            </geometry>
            <material name="">
                <color rgba="0.79216 0.81961 0.93333 1" />
            </material>
        </visual>
        <collision>
            <origin xyz="-0.0045 0 0" rpy="0 0 0" />
            <geometry>
                <box size="0.1045 0.06 0.095" />
            </geometry>
        </collision>
    </link>
    <joint name="L_HipRoll_Joint" type="revolute">
        <origin xyz="0 0 0" rpy="2.77555756156289E-17 1.88969769143558E-16 1.36928250674653E-16" />
        <parent link="L_HipRoll_Link" />
        <child link="L_HipCenter_Link" />
        <axis xyz="1 0 0" />
        <limit lower="-3.14" upper="3.14" effort="500" velocity="100" />
        <dynamics damping="5" />
    </joint>
    <link name="L_Thigh_Link">
        <inertial>
            <origin xyz="-0.00042 0.00032 -0.18904" rpy="0 0 0" />
            <mass value="5.366" />
            <inertia ixx="0.2987" ixy="-4.284E-05" ixz="-0.000196" iyy="0.7088" iyz="0.002406" izz="0.00982" />
        </inertial>
        <visual>
            <origin xyz="0 0 0" rpy="0 0 0" />
            <geometry>
                <mesh filename="package://tocabi_description/meshes/Thigh_L_Link.STL" />
            </geometry>
            <material name="">
                <color rgba="0.79216 0.81961 0.93333 1" />
            </material>
        </visual>
        <collision>
            <origin xyz="0 0 -0.35" rpy="1.570796 0 0" />
            <geometry>
                <cylinder length="0.07763" radius="0.049" />
            </geometry>
        </collision>
        <collision>
            <origin xyz="0 0 -0.1923" rpy="0 0 0" />
            <geometry>
                <cylinder length="0.2175" radius="0.06" />
            </geometry>
        </collision>
    </link>
    <joint name="L_HipPitch_Joint" type="revolute">
        <origin xyz="0 0 0" rpy="-2.77555756156289E-17 -1.88969769143558E-16 -1.36928250674653E-16" />
        <parent link="L_HipCenter_Link" />
        <child link="L_Thigh_Link" />
        <axis xyz="0 1 0" />
        <limit lower="-3.14" upper="3.14" effort="500" velocity="100" />
        <dynamics damping="5" />
    </joint>
    <link name="L_Knee_Link">
        <inertial>
            <origin xyz="0.00429 -0.00214 -0.1428" rpy="0 0 0" />
            <mass value="3.883" />
            <inertia ixx="0.1506" ixy="-2.887E-05" ixz="-0.002607" iyy="0.5588" iyz="-0.001486" izz="0.007451" />
        </inertial>
        <visual>
            <origin xyz="0 0 0" rpy="0 0 0" />
            <geometry>
                <mesh filename="package://tocabi_description/meshes/Knee_L_Link.STL" />
            </geometry>
            <material name="">
                <color rgba="0.79216 0.81961 0.93333 1" />
            </material>
        </visual>
        <collision>
            <origin xyz="0 0 -0.175" rpy="0 0 0" />
            <geometry>
                <cylinder length="0.200" radius="0.06" />
            </geometry>
        </collision>
    </link>
    <joint name="L_Knee_Joint" type="revolute">
        <origin xyz="0 0 -0.350000000000191" rpy="0 0 0" />
        <parent link="L_Thigh_Link" />
        <child link="L_Knee_Link" />
        <axis xyz="0 1 0" />
        <limit lower="-3.14" upper="3.14" effort="500" velocity="100" />
        <dynamics damping="5" />
    </joint>
    <link name="L_AnkleCenter_Link">
        <inertial>
            <origin xyz="-0.00419 0.0018 -0.0003" rpy="0 0 0" />
            <mass value="2.51" />
            <inertia ixx="0.002857" ixy="-1.422E-07" ixz="2.222E-06" iyy="0.4135" iyz="4.611E-06" izz="0.003345" />
        </inertial>
        <visual>
            <origin xyz="0 0 0" rpy="0 0 0" />
            <geometry>
                <mesh filename="package://tocabi_description/meshes/AnkleCenter_L_Link.STL" />
            </geometry>
            <material name="">
                <color rgba="0.79216 0.81961 0.93333 1" />
            </material>
        </visual>
        <collision>
            <origin xyz="-0.0045 0 0" rpy="0 0 0" />
            <geometry>
                <box size="0.1045 0.06 0.095" />
            </geometry>
        </collision>
    </link>
    <joint name="L_AnklePitch_Joint" type="revolute">
        <origin xyz="0 0 -0.350000000051828" rpy="2.57102424745274E-31 -1.5978825624527E-16 1.89651504296143E-16" />
        <parent link="L_Knee_Link" />
        <child link="L_AnkleCenter_Link" />
        <axis xyz="0 1 0" />
        <limit lower="-3.14" upper="3.14" effort="500" velocity="100" />
        <dynamics damping="5" />
    </joint>
    <link name="L_AnkleRoll_Link">
        <inertial>
            <origin xyz="-0.05196 0.00005 -0.0219" rpy="0 0 0" />
            <mass value="1.26426" />
            <inertia ixx="0.418697" ixy="1.5176E-08" ixz="-0.001095976" iyy="0.006211405" iyz="-5.435E-08" izz="0.008575514" />
        </inertial>
        <visual>
            <origin xyz="0 0 0" rpy="0 0 0" />
            <geometry>
                <mesh filename="package://tocabi_description/meshes/AnkleRoll_L_Link.STL" />
            </geometry>
            <material name="">
                <color rgba="0.79216 0.81961 0.93333 1" />
            </material>
        </visual>
        <collision>
            <origin xyz="-0.08875 0 0" rpy="0 -1.5707963 0" />
            <geometry>
                <cylinder length="0.0625" radius="0.045" />
            </geometry>
        </collision>
    </link>
    <joint name="L_AnkleRoll_Joint" type="revolute">
        <origin xyz="0 0 0" rpy="-2.87406507911047E-31 1.5978825624527E-16 -1.89651504296143E-16" />
        <parent link="L_AnkleCenter_Link" />
        <child link="L_AnkleRoll_Link" />
        <axis xyz="1 0 0" />
        <limit lower="-3.14" upper="3.14" effort="500" velocity="100" />
        <dynamics damping="5" />
    </joint>
    <link name="L_Foot_Link">
        <inertial>
            <origin xyz="0.0162 0.00008 -0.1209" rpy="0 0 0" />
            <mass value="2.326" />
            <inertia ixx="0.003386409" ixy="1.1237E-05" ixz="-0.000526477" iyy="0.012600125" iyz="-1.976E-06" izz="0.014296" />
        </inertial>
        <visual>
            <origin xyz="0 0 0" rpy="0 0 0" />
            <geometry>
                <mesh filename="package://tocabi_description/meshes/Foot_Link.STL" />
            </geometry>
            <material name="">
                <color rgba="0.79216 0.81961 0.93333 1" />
            </material>
        </visual>
        <collision>
            <origin xyz="0.03 0 -0.145" rpy="0 0 0" />
            <geometry>
                <box size="0.3 0.17 0.027" />
            </geometry>
        </collision>
        <collision>
            <origin xyz="-0.08875 0 0" rpy="0 -1.5707963 0" />
            <geometry>
                <cylinder length="0.0625" radius="0.045" />
            </geometry>
        </collision>
    </link>
    <joint name="L_Foot_Joint" type="fixed">
        <origin xyz="0 0 0" rpy="0 0 0" />
        <parent link="L_AnkleRoll_Link" />
        <child link="L_Foot_Link" />
        <axis xyz="0 0 0" />
        <limit lower="-3.14" upper="3.14" effort="500" velocity="100" />
        <dynamics damping="5" />
    </joint>
    <link name="Waist1_Link">
        <inertial>
            <origin xyz="0 0 -0.03647" rpy="0 0 0" />
            <mass value="0.89722" />
            <inertia ixx="0.003744227" ixy="-0.000023489" ixz="0.000037149" iyy="0.002030963" iyz="-0.000424890" izz="1.007723743" />
        </inertial>
        <visual>
            <origin xyz="0 0 0" rpy="0 0 0" />
            <geometry>
                <mesh filename="package://tocabi_description/meshes/waist1.STL" />
            </geometry>
            <material name="">
                <color rgba="0.792156862745098 0.819607843137255 0.933333333333333 1" />
            </material>
        </visual>
        <visual>
            <origin xyz="0 0 -0.096" rpy="0 0 0" />
            <geometry>
                <cylinder length="0.02" radius="0.05" />
            </geometry>
            <material name="">
                <color rgba="0.792156862745098 0.819607843137255 0.933333333333333 1" />
            </material>
        </visual>
        <collision>
            <origin xyz="0 0 -0.096" rpy="0 0 0" />
            <geometry>
                <cylinder length="0.02" radius="0.05" />
            </geometry>
        </collision>
        <collision>
            <origin xyz="0 0 -0.081" rpy="0 0 0" />
            <geometry>
                <box size="0.094 0.13 0.01" />
            </geometry>
        </collision>
        <collision>
            <origin xyz="0 0.06 -0.0405" rpy="0 0 0" />
            <geometry>
                <box size="0.094 0.01 0.091" />
            </geometry>
        </collision>
        <collision>
            <origin xyz="0 -0.06 -0.0405" rpy="0 0 0" />
            <geometry>
                <box size="0.094 0.01 0.091" />
            </geometry>
        </collision>
    </link>
    <joint name="Waist1_Joint" type="revolute">
        <origin xyz="0.11 0 0.1979" rpy="0 0 0" />
        <parent link="Pelvis_Link" />
        <child link="Waist1_Link" />
        <axis xyz="0 0 1" />
        <limit lower="-2.094" upper="2.094" effort="500" velocity="100" />
        <dynamics damping="5" />
    </joint>
    <link name="Waist2_Link">
        <inertial>
            <origin xyz="-0.00029 0 0" rpy="0 0 0" />
            <mass value="3.752" />
            <inertia ixx="0.006020606" ixy="0.000011504" ixz="-0.000000053" iyy="1.011708561" iyz="0.000001147" izz="0.007561688" />
        </inertial>
        <visual>
            <origin xyz="0 0 0" rpy="0 0 0" />
            <geometry>
                <mesh filename="package://tocabi_description/meshes/waist2.STL" />
            </geometry>
            <material name="">
                <color rgba="0.792156862745098 0.819607843137255 0.933333333333333 1" />
            </material>
        </visual>
        <collision>
            <origin xyz="0 0 0" rpy="1.570796 0 0" />
            <geometry>
                <cylinder length="0.1" radius="0.055" />
            </geometry>
        </collision>
        <collision>
            <origin xyz="0.02 0 0" rpy="0 0 0" />
            <geometry>
                <box size="0.1 0.1 0.06" />
            </geometry>
        </collision>
        <collision>
            <origin xyz="-0.02 0 0" rpy="0 0 0" />
            <geometry>
                <box size="0.09 0.1 0.091" />
            </geometry>
        </collision>
    </link>
    <joint name="Waist2_Joint" type="revolute">
        <origin xyz="0 0 0" rpy="0 0 0" />
        <parent link="Waist1_Link" />
        <child link="Waist2_Link" />
        <axis xyz="0 1 0" />
        <limit lower="-2.094" upper="2.094" effort="500" velocity="100" />
        <dynamics damping="5" />
    </joint>
    <link name="Upperbody_Link">
        <inertial>
            <origin xyz="-0.07294 0 0.16798" rpy="0 0 0" />
            <mass value="18.13384" />
            <inertia ixx="1.270791438" ixy="0.000113985" ixz="0.029533458" iyy="0.238938452" iyz="-0.000028977" izz="0.179864207" />
        </inertial>
        <visual>
            <origin xyz="0 0 0" rpy="0 0 0" />
            <geometry>
                <mesh filename="package://tocabi_description/meshes/upperbody.STL" />
            </geometry>
            <material name="">
                <color rgba="0.792156862745098 0.819607843137255 0.933333333333333 1" />
            </material>
        </visual>
        <visual>
            <origin xyz="-0.03 0 0.2" rpy="0 0 0" />
            <geometry>
                <box size="0.21 0.22 0.1" />
            </geometry>
            <material name="">
                <color rgba="0.792156862745098 0.819607843137255 0.933333333333333 1" />
            </material>
        </visual>
        <visual>
            <origin xyz="-0.03 0 0.115" rpy="0 0 0" />
            <geometry>
                <box size="0.21 0.11 0.07" />
            </geometry>
            <material name="">
                <color rgba="0.792156862745098 0.819607843137255 0.933333333333333 1" />
            </material>
        </visual>
        <visual>
            <origin xyz="-0.08 0 0.32" rpy="0 0 0" />
            <geometry>
                <box size="0.12 0.07 0.14" />
            </geometry>
            <material name="">
                <color rgba="0.792156862745098 0.819607843137255 0.933333333333333 1" />
            </material>
        </visual>
        <collision>
            <origin xyz="-0.03 0 0.2" rpy="0 0 0" />
            <geometry>
                <box size="0.21 0.22 0.1" />
            </geometry>
        </collision>
        <collision>
            <origin xyz="-0.03 0 0.115" rpy="0 0 0" />
            <geometry>
                <box size="0.21 0.11 0.07" />
            </geometry>
        </collision>
        <collision>
            <origin xyz="-0.08 0 0.32" rpy="0 0 0" />
            <geometry>
                <box size="0.12 0.07 0.14" />
            </geometry>
        </collision>
        <collision>
            <origin xyz="-0.115 0 0.0" rpy="0 1.570796 0" />
            <geometry>
                <cylinder length="0.09" radius="0.054" />
            </geometry>
        </collision>
        <collision>
            <origin xyz="0.023 0.154 0.185" rpy="0 0 0" />
            <geometry>
                <cylinder length="0.07" radius="0.040" />
            </geometry>
        </collision>
        <collision>
            <origin xyz="0.023 -0.154 0.185" rpy="0 0 0" />
            <geometry>
                <cylinder length="0.07" radius="0.040" />
            </geometry>
        </collision>
    </link>
    <joint name="Upperbody_Joint" type="revolute">
        <origin xyz="0 0 0" rpy="0 0 0" />
        <parent link="Waist2_Link" />
        <child link="Upperbody_Link" />
        <axis xyz="-1 0 0" />
        <limit lower="-2.094" upper="2.094" effort="500" velocity="100" />
        <dynamics damping="5" />
    </joint>
    <link name="Neck_Link">
        <inertial>
            <origin xyz="0.0 0 -0.0023" rpy="0 0 0" />
            <mass value="0.248" />
            <inertia ixx="0.000058259" ixy="-0.000000076" ixz="0.000000268" iyy="0.000036489" iyz="-0.000001002" izz="0.000058237" />
        </inertial>
        <visual>
            <origin xyz="0 0 0" rpy="0 0 0" />
            <geometry>
                <mesh filename="package://tocabi_description/meshes/neck.STL" />
            </geometry>
            <material name="">
                <color rgba="0.792156862745098 0.819607843137255 0.933333333333333 1" />
            </material>
        </visual>
        <collision>
            <origin xyz="0 0 0.05" rpy="0 0 0" />
            <geometry>
                <cylinder length="0.043" radius="0.07" />
            </geometry>
        </collision>
    </link>
    <joint name="Neck_Joint" type="revolute">
        <origin xyz="-0.036 0.0 0.3795" rpy="0 0 0" />
        <parent link="Upperbody_Link" />
        <child link="Neck_Link" />
        <axis xyz="0 0 1" />
        <limit lower="-1.54" upper="1.54" effort="500" velocity="100" />
        <dynamics damping="5" />
    </joint>
    <link name="Head_Link">
        <inertial>
            <origin xyz="0.05 0 0.071" rpy="0 0 0" />
            <mass value="1.417" />
            <inertia ixx="0.0079" ixy="0.0" ixz="0.0025" iyy="0.012" iyz="0.0" izz="0.01" />
        </inertial>
        <visual>
            <origin xyz="0.02 0 -0.6" rpy="0 0 0" />
            <geometry>
                <mesh filename="package://tocabi_description/meshes/head.STL" scale="0.001 0.001 0.001" />
            </geometry>
            <material name="">
                <color rgba="0.792156862745098 0.819607843137255 0.933333333333333 1" />
            </material>
        </visual>
        <collision>
            <origin xyz="0 0 0.05" rpy="0 0 0" />
            <geometry>
                <cylinder length="0.043" radius="0.07" />
            </geometry>
        </collision>
    </link>
    <joint name="Head_Joint" type="revolute">
        <origin xyz="0.0 0.0 0.0275" rpy="0 0 0" />
        <parent link="Neck_Link" />
        <child link="Head_Link" />
        <axis xyz="0 1 0" />
        <limit lower="-1.54" upper="1.54" effort="500" velocity="100" />
        <dynamics damping="5" />
    </joint>
    <link name="L_Shoulder1_Link">
        <inertial>
            <origin xyz="-0.00003 0.00397 0.06029" rpy="0 0 0" />
            <mass value="1.6762" />
            <inertia ixx="0.001925606" ixy="0.000001433" ixz="0.000002313" iyy="0.001936576" iyz="0.000078962" izz="0.185330098" />
        </inertial>
        <visual>
            <origin xyz="0 0 0" rpy="0 0 0" />
            <geometry>
                <mesh filename="package://tocabi_description/meshes/L_shoulder1.STL" />
            </geometry>
            <material name="">
                <color rgba="0.792156862745098 0.819607843137255 0.933333333333333 1" />
            </material>
        </visual>
        <collision>
            <origin xyz="0 0 0.05" rpy="0 0 0" />
            <geometry>
                <cylinder length="0.11" radius="0.04" />
            </geometry>
        </collision>
    </link>
    <joint name="L_Shoulder1_Joint" type="revolute">
        <origin xyz="0.023 0.154 0.2275" rpy="0 0 0" />
        <parent link="Upperbody_Link" />
        <child link="L_Shoulder1_Link" />
        <axis xyz="0 0 1" />
        <limit lower="-2.09" upper="1.54" effort="500" velocity="100" />
        <dynamics damping="5" />
    </joint>
    <link name="L_Shoulder2_Link">
        <inertial>
            <origin xyz="0.00107 0.0491 -0.00001" rpy="0 0 0" />
            <mass value="0.4016" />
            <inertia ixx="0.000989903" ixy="0.000028237" ixz="-0.000000465" iyy="0.184275853" iyz="0.000000133" izz="0.001067575" />
        </inertial>
        <visual>
            <origin xyz="0 0 0" rpy="0 0 0" />
            <geometry>
                <mesh filename="package://tocabi_description/meshes/L_shoulder2.STL" />
            </geometry>
            <material name="">
                <color rgba="0.792156862745098 0.819607843137255 0.933333333333333 1" />
            </material>
        </visual>
        <collision>
            <origin xyz="0 0.040 0" rpy="1.570796 0 0" />
            <geometry>
                <cylinder length="0.05" radius="0.04" />
            </geometry>
        </collision>
    </link>
    <joint name="L_Shoulder2_Joint" type="revolute">
        <origin xyz="0 0.0341 0.065" rpy="0 0 0" />
        <parent link="L_Shoulder1_Link" />
        <child link="L_Shoulder2_Link" />
        <axis xyz="0 1 0" />
        <limit lower="-3.14159" upper="3.14159" effort="500" velocity="100" />
        <dynamics damping="5" />
    </joint>
    <link name="L_Shoulder3_Link">
        <inertial>
            <origin xyz="0.00262 0.04826 0.00023" rpy="0 0 0" />
            <mass value="2.90141" />
            <inertia ixx="0.192093159" ixy="-0.000365084" ixz="-0.000002746" iyy="0.002493784" iyz="-0.000023821" izz="0.008296854" />
        </inertial>
        <visual>
            <origin xyz="0 0 0" rpy="0 0 0" />
            <geometry>
                <mesh filename="package://tocabi_description/meshes/L_shoulder3.STL" />
            </geometry>
            <material name="">
                <color rgba="0.792156862745098 0.819607843137255 0.933333333333333 1" />
            </material>
        </visual>
        <collision>
            <origin xyz="0 0.06 0" rpy="1.570796 0 0" />
            <geometry>
                <cylinder length="0.12" radius="0.04" />
            </geometry>
        </collision>
    </link>
    <joint name="L_Shoulder3_Joint" type="revolute">
        <origin xyz="0 0.115 0" rpy="0 0 0" />
        <parent link="L_Shoulder2_Link" />
        <child link="L_Shoulder3_Link" />
        <axis xyz="-1 0 0" />
        <limit lower="-1.9199" upper="1.9199" effort="500" velocity="100" />
        <dynamics damping="5" />
    </joint>
    <link name="L_Armlink_Link">
        <inertial>
            <origin xyz="-0.01896 0.11642 -0.0119" rpy="0 0 0" />
            <mass value="0.58517" />
            <inertia ixx="0.002878609" ixy="0.000302586" ixz="-0.000036001" iyy="0.184381923" iyz="0.000398377" izz="0.003117058" />
        </inertial>
        <visual>
            <origin xyz="0 0 0" rpy="0 0 0" />
            <geometry>
                <mesh filename="package://tocabi_description/meshes/L_arm.STL" />
            </geometry>
            <material name="">
                <color rgba="0.792156862745098 0.819607843137255 0.933333333333333 1" />
            </material>
        </visual>
        <collision>
            <origin xyz="0 0.08 0" rpy="1.570796 0 0" />
            <geometry>
                <cylinder length="0.16" radius="0.04" />
            </geometry>
        </collision>
    </link>
    <joint name="L_Armlink_Joint" type="revolute">
        <origin xyz="0 0.1281 0" rpy="0 0 0" />
        <parent link="L_Shoulder3_Link" />
        <child link="L_Armlink_Link" />
        <axis xyz="0 1 0" />
        <limit lower="-3.14159" upper="3.14159" effort="500" velocity="100" />
        <dynamics damping="5" />
    </joint>
    <link name="L_Elbow_Link">
        <inertial>
            <origin xyz="-0.00136 0.05256 0.01764" rpy="0 0 0" />
            <mass value="2.06511" />
            <inertia ixx="0.055865466" ixy="0.000151764" ixz="0.000055158" iyy="0.001895543" iyz="0.001530917" izz="0.005958821" />
        </inertial>
        <visual>
            <origin xyz="0 0 0" rpy="0 0 0" />
            <geometry>
                <mesh filename="package://tocabi_description/meshes/L_elbow.STL" />
            </geometry>
            <material name="">
                <color rgba="0.792156862745098 0.819607843137255 0.933333333333333 1" />
            </material>
        </visual>
        <collision>
            <origin xyz="0 0.08 0.0325" rpy="1.570796 0 0" />
            <geometry>
                <cylinder length="0.08" radius="0.04" />
            </geometry>
        </collision>
        <collision>
            <origin xyz="0 0 0" rpy="0 1.570796 0" />
            <geometry>
                <cylinder length="0.08" radius="0.04" />
            </geometry>
        </collision>
    </link>
    <joint name="L_Elbow_Joint" type="revolute">
        <origin xyz="0 0.207 -0.0325" rpy="0 0 0" />
        <parent link="L_Armlink_Link" />
        <child link="L_Elbow_Link" />
        <axis xyz="1 0 0" />
        <limit lower="-3.14159" upper="2.8" effort="500" velocity="100" />
        <dynamics damping="5" />
    </joint>
    <link name="L_Forearm_Link">
        <inertial>
            <origin xyz="-0.01426 0.0767 0.00033" rpy="0 0 0" />
            <mass value="0.35234" />
            <inertia ixx="0.001053636" ixy="0.000084568" ixz="0.000022117" iyy="0.049889479" iyz="0.000019539" izz="0.001266418" />
        </inertial>
        <visual>
            <origin xyz="0 0 0" rpy="0 0 0" />
            <geometry>
                <mesh filename="package://tocabi_description/meshes/L_forearm.STL" />
            </geometry>
            <material name="">
                <color rgba="0.792156862745098 0.819607843137255 0.933333333333333 1" />
            </material>
        </visual>
        <collision>
            <origin xyz="0 0.05 0" rpy="1.570796 0 0" />
            <geometry>
                <cylinder length="0.1" radius="0.04" />
            </geometry>
        </collision>
        <collision>
            <origin xyz="0 0.1451 0" rpy="0 1.570796 0" />
            <geometry>
                <cylinder length="0.08" radius="0.025" />
            </geometry>
        </collision>
    </link>
    <joint name="L_Forearm_Joint" type="revolute">
        <origin xyz="0 0.1244 0.0325" rpy="0 0 0" />
        <parent link="L_Elbow_Link" />
        <child link="L_Forearm_Link" />
        <axis xyz="0 1 0" />
        <limit lower="-3.14159" upper="3.14159" effort="500" velocity="100" />
        <dynamics damping="5" />
    </joint>
    <link name="L_Wrist1_Link">
        <inertial>
            <origin xyz="-0.00158 0.02153 0.00003" rpy="0 0 0" />
            <mass value="0.70923" />
            <inertia ixx="0.015205197" ixy="0.000024218" ixz="-0.000000263" iyy="0.000396376" iyz="0.000000688" izz="0.000683187" />
        </inertial>
        <visual>
            <origin xyz="0 0 0" rpy="0 0 0" />
            <geometry>
                <mesh filename="package://tocabi_description/meshes/L_wrist1.STL" />
            </geometry>
            <material name="">
                <color rgba="0.792156862745098 0.819607843137255 0.933333333333333 1" />
            </material>
        </visual>
        <collision>
            <origin xyz="0 0.046 0" rpy="0 0 0" />
            <geometry>
                <cylinder length="0.06" radius="0.02" />
            </geometry>
        </collision>
    </link>
    <joint name="L_Wrist1_Joint" type="revolute">
        <origin xyz="0 0.1451 0" rpy="0 0 0" />
        <parent link="L_Forearm_Link" />
        <child link="L_Wrist1_Link" />
        <axis xyz="1 0 0" />
        <limit lower="-3.14159" upper="3.14159" effort="500" velocity="100" />
        <dynamics damping="5" />
    </joint>
    <link name="L_Wrist2_Link">
        <inertial>
            <origin xyz="0.00063 0.0636 0.00178" rpy="0 0 0" />
            <mass value="0.1" />
            <inertia ixx="0.000865450" ixy="0" ixz="0" iyy="0.000696917" iyz="0" izz="0.015377823" />
        </inertial>
        <visual>
            <origin xyz="0 0 -0.025" rpy="0 0 0" />
            <geometry>
                <box size="0.06 0.06 0.02" />
            </geometry>
            <material name="">
                <color rgba="0.792156862745098 0.819607843137255 0.933333333333333 1" />
            </material>
        </visual>
        <collision>
            <origin xyz="0 0 -0.025" rpy="0 0 0" />
            <geometry>
                <box size="0.06 0.06 0.02" />
            </geometry>
        </collision>
    </link>
    <joint name="L_Wrist2_Joint" type="revolute">
        <origin xyz="0 0.046 0" rpy="1.5708 3.1415 0" />
        <parent link="L_Wrist1_Link" />
        <child link="L_Wrist2_Link" />
        <axis xyz="0 1 0" />
        <limit lower="-2.094" upper="2.094" effort="500" velocity="100" />
        <dynamics damping="5" />
    </joint>
    <link name="R_Shoulder1_Link">
        <inertial>
            <origin xyz="-0.00003 -0.00397 0.06029" rpy="0 0 0" />
            <mass value="1.6762" />
            <inertia ixx="0.001925606" ixy="-0.000001433" ixz="0.000002313" iyy="0.001936576" iyz="-0.000078962" izz="0.185330098" />
        </inertial>
        <visual>
            <origin xyz="0 0 0" rpy="0 0 0" />
            <geometry>
                <mesh filename="package://tocabi_description/meshes/R_shoulder1.STL" />
            </geometry>
            <material name="">
                <color rgba="0.792156862745098 0.819607843137255 0.933333333333333 1" />
            </material>
        </visual>
        <collision>
            <origin xyz="0 0 0.05" rpy="0 0 0" />
            <geometry>
                <cylinder length="0.11" radius="0.04" />
            </geometry>
        </collision>
    </link>
    <joint name="R_Shoulder1_Joint" type="revolute">
        <origin xyz="0.023 -0.154 0.2275" rpy="0 0 0" />
        <parent link="Upperbody_Link" />
        <child link="R_Shoulder1_Link" />
        <axis xyz="0 0 1" />
        <limit lower="-1.54" upper="2.09" effort="500" velocity="100" />
        <dynamics damping="5" />
    </joint>
    <link name="R_Shoulder2_Link">
        <inertial>
            <origin xyz="0.00107 -0.0491 -0.00001" rpy="0 0 0" />
            <mass value="0.4016" />
            <inertia ixx="0.000989903" ixy="-0.000028237" ixz="-0.000000465" iyy="0.184275853" iyz="-0.000000133" izz="0.001067575" />
        </inertial>
        <visual>
            <origin xyz="0 0 0" rpy="0 0 0" />
            <geometry>
                <mesh filename="package://tocabi_description/meshes/R_shoulder2.STL" />
            </geometry>
            <material name="">
                <color rgba="0.792156862745098 0.819607843137255 0.933333333333333 1" />
            </material>
        </visual>
        <collision>
            <origin xyz="0 -0.040 0" rpy="1.570796 0 0" />
            <geometry>
                <cylinder length="0.05" radius="0.04" />
            </geometry>
        </collision>
    </link>
    <joint name="R_Shoulder2_Joint" type="revolute">
        <origin xyz="0 -0.0341 0.065" rpy="0 0 0" />
        <parent link="R_Shoulder1_Link" />
        <child link="R_Shoulder2_Link" />
        <axis xyz="0 -1 0" />
        <limit lower="-3.14159" upper="3.14159" effort="500" velocity="100" />
        <dynamics damping="5" />
    </joint>
    <link name="R_Shoulder3_Link">
        <inertial>
            <origin xyz="0.00262 -0.04826 0.00023" rpy="0 0 0" />
            <mass value="2.90141" />
            <inertia ixx="0.192093159" ixy="0.000365084" ixz="-0.000002746" iyy="0.002493784" iyz="0.000023821" izz="0.008296854" />
        </inertial>
        <visual>
            <origin xyz="0 0 0" rpy="0 0 0" />
            <geometry>
                <mesh filename="package://tocabi_description/meshes/R_shoulder3.STL" />
            </geometry>
            <material name="">
                <color rgba="0.792156862745098 0.819607843137255 0.933333333333333 1" />
            </material>
        </visual>
        <collision>
            <origin xyz="0 -0.06 0" rpy="1.570796 0 0" />
            <geometry>
                <cylinder length="0.12" radius="0.04" />
            </geometry>
        </collision>
    </link>
    <joint name="R_Shoulder3_Joint" type="revolute">
        <origin xyz="0 -0.115 0" rpy="0 0 0" />
        <parent link="R_Shoulder2_Link" />
        <child link="R_Shoulder3_Link" />
        <axis xyz="-1 0 0" />
        <limit lower="-1.9199" upper="1.9199" effort="500" velocity="100" />
        <dynamics damping="5" />
    </joint>
    <link name="R_Armlink_Link">
        <inertial>
            <origin xyz="-0.01896 -0.11642 -0.0119" rpy="0 0 0" />
            <mass value="0.58517" />
            <inertia ixx="0.002878609" ixy="-0.000302586" ixz="-0.000036001" iyy="0.184381923" iyz="-0.000398377" izz="0.003117058" />
        </inertial>
        <visual>
            <origin xyz="0 0 0" rpy="0 0 0" />
            <geometry>
                <mesh filename="package://tocabi_description/meshes/R_arm.STL" />
            </geometry>
            <material name="">
                <color rgba="0.792156862745098 0.819607843137255 0.933333333333333 1" />
            </material>
        </visual>
        <collision>
            <origin xyz="0 -0.08 0" rpy="1.570796 0 0" />
            <geometry>
                <cylinder length="0.16" radius="0.04" />
            </geometry>
        </collision>
    </link>
    <joint name="R_Armlink_Joint" type="revolute">
        <origin xyz="0 -0.1281 0" rpy="0 0 0" />
        <parent link="R_Shoulder3_Link" />
        <child link="R_Armlink_Link" />
        <axis xyz="0 -1 0" />
        <limit lower="-3.14159" upper="3.14159" effort="500" velocity="100" />
        <dynamics damping="5" />
    </joint>
    <link name="R_Elbow_Link">
        <inertial>
            <origin xyz="-0.00136 -0.05256 0.01764" rpy="0 0 0" />
            <mass value="2.06511" />
            <inertia ixx="0.055865466" ixy="-0.000151764" ixz="0.000055158" iyy="0.001895543" iyz="-0.001530917" izz="0.005958821" />
        </inertial>
        <visual>
            <origin xyz="0 0 0" rpy="0 0 0" />
            <geometry>
                <mesh filename="package://tocabi_description/meshes/R_elbow.STL" />
            </geometry>
            <material name="">
                <color rgba="0.792156862745098 0.819607843137255 0.933333333333333 1" />
            </material>
        </visual>
        <collision>
            <origin xyz="0 -0.08 0.0325" rpy="1.570796 0 0" />
            <geometry>
                <cylinder length="0.08" radius="0.04" />
            </geometry>
        </collision>
        <collision>
            <origin xyz="0 0 0" rpy="0 1.570796 0" />
            <geometry>
                <cylinder length="0.08" radius="0.04" />
            </geometry>
        </collision>
    </link>
    <joint name="R_Elbow_Joint" type="revolute">
        <origin xyz="0 -0.207 -0.0325" rpy="0 0 0" />
        <parent link="R_Armlink_Link" />
        <child link="R_Elbow_Link" />
        <axis xyz="1 0 0" />
        <limit lower="-2.967" upper="3.14159" effort="500" velocity="100" />
        <dynamics damping="5" />
    </joint>
    <link name="R_Forearm_Link">
        <inertial>
            <origin xyz="-0.01426 -0.0767 0.00033" rpy="0 0 0" />
            <mass value="0.35234" />
            <inertia ixx="0.001053636" ixy="-0.000084568" ixz="0.000022117" iyy="0.049889479" iyz="-0.000019539" izz="0.001266418" />
        </inertial>
        <visual>
            <origin xyz="0 0 0" rpy="0 0 0" />
            <geometry>
                <mesh filename="package://tocabi_description/meshes/R_forearm.STL" />
            </geometry>
            <material name="">
                <color rgba="0.792156862745098 0.819607843137255 0.933333333333333 1" />
            </material>
        </visual>
        <collision>
            <origin xyz="0 -0.05 0" rpy="1.570796 0 0" />
            <geometry>
                <cylinder length="0.1" radius="0.04" />
            </geometry>
        </collision>
        <collision>
            <origin xyz="0 -0.1451 0" rpy="0 1.570796 0" />
            <geometry>
                <cylinder length="0.08" radius="0.025" />
            </geometry>
        </collision>
    </link>
    <joint name="R_Forearm_Joint" type="revolute">
        <origin xyz="0 -0.1244 0.0325" rpy="0 0 0" />
        <parent link="R_Elbow_Link" />
        <child link="R_Forearm_Link" />
        <axis xyz="0 -1 0" />
        <limit lower="-3.14159" upper="3.14159" effort="500" velocity="100" />
        <dynamics damping="5" />
    </joint>
    <link name="R_Wrist1_Link">
        <inertial>
            <origin xyz="-0.00158 -0.02153 0.00003" rpy="0 0 0" />
            <mass value="0.70923" />
            <inertia ixx="0.015205197" ixy="-0.000024218" ixz="-0.000000263" iyy="0.000396376" iyz="-0.000000688" izz="0.000683187" />
        </inertial>
        <visual>
            <origin xyz="0 0 0" rpy="0 0 0" />
            <geometry>
                <mesh filename="package://tocabi_description/meshes/R_wrist1.STL" />
            </geometry>
            <material name="">
                <color rgba="0.792156862745098 0.819607843137255 0.933333333333333 1" />
            </material>
        </visual>
        <collision>
            <origin xyz="0 -0.046 0" rpy="0 0 0" />
            <geometry>
                <cylinder length="0.06" radius="0.02" />
            </geometry>
        </collision>
    </link>
    <joint name="R_Wrist1_Joint" type="revolute">
        <origin xyz="0 -0.1451 0" rpy="0 0 0" />
        <parent link="R_Forearm_Link" />
        <child link="R_Wrist1_Link" />
        <axis xyz="1 0 0" />
        <limit lower="-3.14159" upper="3.14159" effort="500" velocity="100" />
        <dynamics damping="5" />
    </joint>
    <link name="R_Wrist2_Link">
        <inertial>
            <origin xyz="0.00063 -0.0636 0.00178" rpy="0 0 0" />
            <mass value="0.1" />
            <inertia ixx="0.000865450" ixy="0" ixz="0" iyy="0.000696917" iyz="0" izz="0.015377823" />
        </inertial>
        <visual>
            <origin xyz="0 0 -0.025" rpy="0 0 0" />
            <geometry>
                <box size="0.06 0.06 0.02" />
            </geometry>
            <material name="">
                <color rgba="0.792156862745098 0.819607843137255 0.933333333333333 1" />
            </material>
        </visual>
        <collision>
            <origin xyz="0 0 -0.025" rpy="0 0 0" />
            <geometry>
                <box size="0.06 0.06 0.02" />
            </geometry>
        </collision>
    </link>
    <joint name="R_Wrist2_Joint" type="revolute">
        <origin xyz="0 -0.046 0" rpy="-1.5708 3.1415 0" />
        <parent link="R_Wrist1_Link" />
        <child link="R_Wrist2_Link" />
        <axis xyz="0 -1 0" />
        <limit lower="-2.094" upper="2.094" effort="500" velocity="100" />
        <dynamics damping="5" />
    </joint>
    <!--sy hand-->
    <material name="silver">
        <color rgba="0.700 0.700 0.700 1.000" />
    </material>
    <link name="palm">
        <inertial>
            <origin rpy="0 0 0" xyz="0.00012921570168839317 0.017296271435922838 0.004513375763540404" />
            <mass value="0.038866249408726565" />
            <inertia ixx="1.6e-05" ixy="1e-06" ixz="1e-06" iyy="2.3e-05" iyz="-2e-06" izz="2.4e-05" />
        </inertial>
        <visual>
            <origin rpy="0 0 0" xyz="0 0 0" />
            <geometry>
                <mesh filename="package://hand_urdf_description/meshes/base_link.stl" scale="0.001 0.001 0.001" />
            </geometry>
            <material name="silver" />
        </visual>
        <collision>
            <origin rpy="0 0 0" xyz="0 0 0" />
            <geometry>
                <mesh filename="package://hand_urdf_description/meshes/base_link.stl" scale="0.001 0.001 0.001" />
            </geometry>
        </collision>
    </link>
    <joint name="R_Wrist_2_Hand_Joint" type="fixed">
        <parent link="R_Wrist2_Link" />
        <child link="palm" />
        <origin xyz="0 0 -0.035" rpy="-1.5707963 0 0" />
    </joint>
    <link name="mcp2_1">
        <inertial>
            <origin rpy="0 0 0" xyz="-0.000857219821930856 0.008425276895379877 0.008651662245754697" />
            <mass value="0.015089936324531419" />
            <inertia ixx="2e-06" ixy="0.0" ixz="0.0" iyy="1e-06" iyz="-0.0" izz="2e-06" />
        </inertial>
        <visual>
            <origin rpy="0 0 0" xyz="0.029022 -0.100047 0.013279" />
            <geometry>
                <mesh filename="package://hand_urdf_description/meshes/mcp2_1.stl" scale="0.001 0.001 0.001" />
            </geometry>
            <material name="silver" />
        </visual>
        <collision>
            <origin rpy="0 0 0" xyz="0.029022 -0.100047 0.013279" />
            <geometry>
                <mesh filename="package://hand_urdf_description/meshes/mcp2_1.stl" scale="0.001 0.001 0.001" />
            </geometry>
        </collision>
    </link>
    <link name="pp2_1">
        <inertial>
            <origin rpy="0 0 0" xyz="0.005589631674371154 0.02220035094602557 0.0017282537013605936" />
            <mass value="0.012568722734729351" />
            <inertia ixx="3e-06" ixy="0.0" ixz="0.0" iyy="2e-06" iyz="-0.0" izz="3e-06" />
        </inertial>
        <visual>
            <origin rpy="0 0 0" xyz="0.037975 -0.114727 0.00277" />
            <geometry>
                <mesh filename="package://hand_urdf_description/meshes/pp2_1.stl" scale="0.001 0.001 0.001" />
            </geometry>
            <material name="silver" />
        </visual>
        <collision>
            <origin rpy="0 0 0" xyz="0.037975 -0.114727 0.00277" />
            <geometry>
                <mesh filename="package://hand_urdf_description/meshes/pp2_1.stl" scale="0.001 0.001 0.001" />
            </geometry>
        </collision>
    </link>
    <link name="mp2_1">
        <inertial>
            <origin rpy="0 0 0" xyz="0.006764528698269524 0.014467776415687972 0.0012618718592496685" />
            <mass value="0.012984163668630283" />
            <inertia ixx="2e-06" ixy="0.0" ixz="0.0" iyy="1e-06" iyz="-0.0" izz="2e-06" />
        </inertial>
        <visual>
            <origin rpy="0 0 0" xyz="0.041906 -0.154536 0.002803" />
            <geometry>
                <mesh filename="package://hand_urdf_description/meshes/mp2_1.stl" scale="0.001 0.001 0.001" />
            </geometry>
            <material name="silver" />
        </visual>
        <collision>
            <origin rpy="0 0 0" xyz="0.041906 -0.154536 0.002803" />
            <geometry>
                <mesh filename="package://hand_urdf_description/meshes/mp2_1.stl" scale="0.001 0.001 0.001" />
            </geometry>
        </collision>
    </link>
    <link name="dp2_1">
        <inertial>
            <origin rpy="0 0 0" xyz="0.00429284844540978 0.014295948406414294 -0.0002467668250413545" />
            <mass value="0.015173806174410396" />
            <inertia ixx="1e-06" ixy="0.0" ixz="-0.0" iyy="1e-06" iyz="0.0" izz="1e-06" />
        </inertial>
        <visual>
            <origin rpy="0 0 0" xyz="0.041819 -0.182648 0.002784" />
            <geometry>
                <mesh filename="package://hand_urdf_description/meshes/dp2_1.stl" scale="0.001 0.001 0.001" />
            </geometry>
            <material name="silver" />
        </visual>
        <collision>
            <origin rpy="0 0 0" xyz="0.041819 -0.182648 0.002784" />
            <geometry>
                <mesh filename="package://hand_urdf_description/meshes/dp2_1.stl" scale="0.001 0.001 0.001" />
            </geometry>
        </collision>
    </link>
    <link name="meta2_1">
        <inertial>
            <origin rpy="0 0 0" xyz="-0.01211260735781576 0.02648361887802418 -0.013626030591322096" />
            <mass value="0.08275708846623805" />
            <inertia ixx="2.6e-05" ixy="1e-06" ixz="-0.0" iyy="1.2e-05" iyz="4e-06" izz="2e-05" />
        </inertial>
        <visual>
            <origin rpy="0 0 0" xyz="0.01455 -0.042738 -0.019873" />
            <geometry>
                <mesh filename="package://hand_urdf_description/meshes/meta2_1.stl" scale="0.001 0.001 0.001" />
            </geometry>
            <material name="silver" />
        </visual>
        <collision>
            <origin rpy="0 0 0" xyz="0.01455 -0.042738 -0.019873" />
            <geometry>
                <mesh filename="package://hand_urdf_description/meshes/meta2_1.stl" scale="0.001 0.001 0.001" />
            </geometry>
        </collision>
    </link>
    <link name="meta1_1">
        <inertial>
            <origin rpy="0 0 0" xyz="-0.01433264799255881 0.013595958407209792 -0.025367779301763302" />
            <mass value="0.08275708846623805" />
            <inertia ixx="1.8e-05" ixy="4e-06" ixz="-4e-06" iyy="1.9e-05" iyz="6e-06" izz="2.1e-05" />
        </inertial>
        <visual>
            <origin rpy="0 0 0" xyz="0.001495 -0.018282 -0.014265" />
            <geometry>
                <mesh filename="package://hand_urdf_description/meshes/meta1_1.stl" scale="0.001 0.001 0.001" />
            </geometry>
            <material name="silver" />
        </visual>
        <collision>
            <origin rpy="0 0 0" xyz="0.001495 -0.018282 -0.014265" />
            <geometry>
                <mesh filename="package://hand_urdf_description/meshes/meta1_1.stl" scale="0.001 0.001 0.001" />
            </geometry>
        </collision>
    </link>
    <link name="mcp1_1">
        <inertial>
            <origin rpy="0 0 0" xyz="-0.011892392991186895 -0.001978714513159799 0.0011010693501598903" />
            <mass value="0.015089936324531419" />
            <inertia ixx="1e-06" ixy="0.0" ixz="-0.0" iyy="2e-06" iyz="0.0" izz="2e-06" />
        </inertial>
        <visual>
            <origin rpy="0 0 0" xyz="0.029913 -0.05726 0.033338" />
            <geometry>
                <mesh filename="package://hand_urdf_description/meshes/mcp1_1.stl" scale="0.001 0.001 0.001" />
            </geometry>
            <material name="silver" />
        </visual>
        <collision>
            <origin rpy="0 0 0" xyz="0.029913 -0.05726 0.033338" />
            <geometry>
                <mesh filename="package://hand_urdf_description/meshes/mcp1_1.stl" scale="0.001 0.001 0.001" />
            </geometry>
        </collision>
    </link>
    <link name="pp1_1">
        <inertial>
            <origin rpy="0 0 0" xyz="-0.018351787155970807 0.003166558534248194 -0.013426634251556484" />
            <mass value="0.012568722734729351" />
            <inertia ixx="2e-06" ixy="0.0" ixz="-0.0" iyy="3e-06" iyz="-0.0" izz="3e-06" />
        </inertial>
        <visual>
            <origin rpy="0 0 0" xyz="0.048881 -0.061771 0.028246" />
            <geometry>
                <mesh filename="package://hand_urdf_description/meshes/pp1_1.stl" scale="0.001 0.001 0.001" />
            </geometry>
            <material name="silver" />
        </visual>
        <collision>
            <origin rpy="0 0 0" xyz="0.048881 -0.061771 0.028246" />
            <geometry>
                <mesh filename="package://hand_urdf_description/meshes/pp1_1.stl" scale="0.001 0.001 0.001" />
            </geometry>
        </collision>
    </link>
    <link name="mp1_1">
        <inertial>
            <origin rpy="0 0 0" xyz="-0.012268990295802334 0.010230288629700227 0.0012193187905829156" />
            <mass value="0.012984163668630283" />
            <inertia ixx="1e-06" ixy="0.0" ixz="-0.0" iyy="2e-06" iyz="0.0" izz="2e-06" />
        </inertial>
        <visual>
            <origin rpy="0 0 0" xyz="0.081016 -0.068487 0.055859" />
            <geometry>
                <mesh filename="package://hand_urdf_description/meshes/mp1_1.stl" scale="0.001 0.001 0.001" />
            </geometry>
            <material name="silver" />
        </visual>
        <collision>
            <origin rpy="0 0 0" xyz="0.081016 -0.068487 0.055859" />
            <geometry>
                <mesh filename="package://hand_urdf_description/meshes/mp1_1.stl" scale="0.001 0.001 0.001" />
            </geometry>
        </collision>
    </link>
    <link name="dp1_1">
        <inertial>
            <origin rpy="0 0 0" xyz="-0.010958343233780934 0.0024543414174510725 -0.009836853940340486" />
            <mass value="0.015173806174410396" />
            <inertia ixx="1e-06" ixy="0.0" ixz="-0.0" iyy="1e-06" iyz="0.0" izz="1e-06" />
        </inertial>
        <visual>
            <origin rpy="0 0 0" xyz="0.104413 -0.088938 0.056639" />
            <geometry>
                <mesh filename="package://hand_urdf_description/meshes/dp1_1.stl" scale="0.001 0.001 0.001" />
            </geometry>
            <material name="silver" />
        </visual>
        <collision>
            <origin rpy="0 0 0" xyz="0.104413 -0.088938 0.056639" />
            <geometry>
                <mesh filename="package://hand_urdf_description/meshes/dp1_1.stl" scale="0.001 0.001 0.001" />
            </geometry>
        </collision>
    </link>
    <link name="meta3_1">
        <inertial>
            <origin rpy="0 0 0" xyz="-0.009999620624593057 0.027434425012110977 -0.01345837781645952" />
            <mass value="0.08275708846623805" />
            <inertia ixx="2.6e-05" ixy="-0.0" ixz="0.0" iyy="1.2e-05" iyz="4e-06" izz="2e-05" />
        </inertial>
        <visual>
            <origin rpy="0 0 0" xyz="-0.01045 -0.042738 -0.019873" />
            <geometry>
                <mesh filename="package://hand_urdf_description/meshes/meta3_1.stl" scale="0.001 0.001 0.001" />
            </geometry>
            <material name="silver" />
        </visual>
        <collision>
            <origin rpy="0 0 0" xyz="-0.01045 -0.042738 -0.019873" />
            <geometry>
                <mesh filename="package://hand_urdf_description/meshes/meta3_1.stl" scale="0.001 0.001 0.001" />
            </geometry>
        </collision>
    </link>
    <link name="mcp3_1">
        <inertial>
            <origin rpy="0 0 0" xyz="3.793755412869826e-07 0.008462389758387132 0.008657702228539479" />
            <mass value="0.015089936324531419" />
            <inertia ixx="2e-06" ixy="0.0" ixz="-0.0" iyy="1e-06" iyz="-0.0" izz="2e-06" />
        </inertial>
        <visual>
            <origin rpy="0 0 0" xyz="-0.00045 -0.101099 0.013093" />
            <geometry>
                <mesh filename="package://hand_urdf_description/meshes/mcp3_1.stl" scale="0.001 0.001 0.001" />
            </geometry>
            <material name="silver" />
        </visual>
        <collision>
            <origin rpy="0 0 0" xyz="-0.00045 -0.101099 0.013093" />
            <geometry>
                <mesh filename="package://hand_urdf_description/meshes/mcp3_1.stl" scale="0.001 0.001 0.001" />
            </geometry>
        </collision>
    </link>
    <link name="pp3_1">
        <inertial>
            <origin rpy="0 0 0" xyz="-0.007499620582276984 0.021637222266037773 0.0016292944075148592" />
            <mass value="0.012568722734729351" />
            <inertia ixx="3e-06" ixy="0.0" ixz="-0.0" iyy="2e-06" iyz="-0.0" izz="3e-06" />
        </inertial>
        <visual>
            <origin rpy="0 0 0" xyz="-0.00795 -0.116487 0.00246" />
            <geometry>
                <mesh filename="package://hand_urdf_description/meshes/pp3_1.stl" scale="0.001 0.001 0.001" />
            </geometry>
            <material name="silver" />
        </visual>
        <collision>
            <origin rpy="0 0 0" xyz="-0.00795 -0.116487 0.00246" />
            <geometry>
                <mesh filename="package://hand_urdf_description/meshes/pp3_1.stl" scale="0.001 0.001 0.001" />
            </geometry>
        </collision>
    </link>
    <link name="mp3_1">
        <inertial>
            <origin rpy="0 0 0" xyz="0.00800037894498693 0.013832153666036212 0.0011508083582961706" />
            <mass value="0.012984163668630283" />
            <inertia ixx="2e-06" ixy="0.0" ixz="-0.0" iyy="1e-06" iyz="-0.0" izz="2e-06" />
        </inertial>
        <visual>
            <origin rpy="0 0 0" xyz="0.00755 -0.156487 0.00246" />
            <geometry>
                <mesh filename="package://hand_urdf_description/meshes/mp3_1.stl" scale="0.001 0.001 0.001" />
            </geometry>
            <material name="silver" />
        </visual>
        <collision>
            <origin rpy="0 0 0" xyz="0.00755 -0.156487 0.00246" />
            <geometry>
                <mesh filename="package://hand_urdf_description/meshes/mp3_1.stl" scale="0.001 0.001 0.001" />
            </geometry>
        </collision>
    </link>
    <link name="dp3_1">
        <inertial>
            <origin rpy="0 0 0" xyz="-0.005499620624595949 0.01387486124955059 -0.00032075053450385683" />
            <mass value="0.015173806174410396" />
            <inertia ixx="1e-06" ixy="0.0" ixz="-0.0" iyy="1e-06" iyz="0.0" izz="1e-06" />
        </inertial>
        <visual>
            <origin rpy="0 0 0" xyz="-0.00595 -0.184487 0.00246" />
            <geometry>
                <mesh filename="package://hand_urdf_description/meshes/dp3_1.stl" scale="0.001 0.001 0.001" />
            </geometry>
            <material name="silver" />
        </visual>
        <collision>
            <origin rpy="0 0 0" xyz="-0.00595 -0.184487 0.00246" />
            <geometry>
                <mesh filename="package://hand_urdf_description/meshes/dp3_1.stl" scale="0.001 0.001 0.001" />
            </geometry>
        </collision>
    </link>
    <link name="meta4_1">
        <inertial>
            <origin rpy="0 0 0" xyz="-0.00781123734537462 0.028200617914747858 -0.013323778438551112" />
            <mass value="0.08275708846623805" />
            <inertia ixx="2.6e-05" ixy="-1e-06" ixz="0.0" iyy="1.2e-05" iyz="4e-06" izz="2e-05" />
        </inertial>
        <visual>
            <origin rpy="0 0 0" xyz="-0.035255 -0.033939 -0.018322" />
            <geometry>
                <mesh filename="package://hand_urdf_description/meshes/meta4_1.stl" scale="0.001 0.001 0.001" />
            </geometry>
            <material name="silver" />
        </visual>
        <collision>
            <origin rpy="0 0 0" xyz="-0.035255 -0.033939 -0.018322" />
            <geometry>
                <mesh filename="package://hand_urdf_description/meshes/meta4_1.stl" scale="0.001 0.001 0.001" />
            </geometry>
        </collision>
    </link>
    <link name="mcp4_1">
        <inertial>
            <origin rpy="0 0 0" xyz="0.0008573751190080851 0.008425275932080492 0.008650914398521567" />
            <mass value="0.015089936324531419" />
            <inertia ixx="2e-06" ixy="-0.0" ixz="-0.0" iyy="1e-06" iyz="-0.0" izz="2e-06" />
        </inertial>
        <visual>
            <origin rpy="0 0 0" xyz="-0.029803 -0.092965 0.014527" />
            <geometry>
                <mesh filename="package://hand_urdf_description/meshes/mcp4_1.stl" scale="0.001 0.001 0.001" />
            </geometry>
            <material name="silver" />
        </visual>
        <collision>
            <origin rpy="0 0 0" xyz="-0.029803 -0.092965 0.014527" />
            <geometry>
                <mesh filename="package://hand_urdf_description/meshes/mcp4_1.stl" scale="0.001 0.001 0.001" />
            </geometry>
        </collision>
    </link>
    <link name="pp4_1">
        <inertial>
            <origin rpy="0 0 0" xyz="-0.005589476293251516 0.02220034997548516 0.0017285058528506928" />
            <mass value="0.012568722734729351" />
            <inertia ixx="3e-06" ixy="-0.0" ixz="-0.0" iyy="2e-06" iyz="-0.0" izz="3e-06" />
        </inertial>
        <visual>
            <origin rpy="0 0 0" xyz="-0.038756 -0.107645 0.004019" />
            <geometry>
                <mesh filename="package://hand_urdf_description/meshes/pp4_1.stl" scale="0.001 0.001 0.001" />
            </geometry>
            <material name="silver" />
        </visual>
        <collision>
            <origin rpy="0 0 0" xyz="-0.038756 -0.107645 0.004019" />
            <geometry>
                <mesh filename="package://hand_urdf_description/meshes/pp4_1.stl" scale="0.001 0.001 0.001" />
            </geometry>
        </collision>
    </link>
    <link name="mp4_1">
        <inertial>
            <origin rpy="0 0 0" xyz="0.009174625740975717 0.013093775526298868 0.0010201240250489563" />
            <mass value="0.012984163668630283" />
            <inertia ixx="2e-06" ixy="-0.0" ixz="-0.0" iyy="1e-06" iyz="-0.0" izz="2e-06" />
        </inertial>
        <visual>
            <origin rpy="0 0 0" xyz="-0.026748 -0.148828 0.00381" />
            <geometry>
                <mesh filename="package://hand_urdf_description/meshes/mp4_1.stl" scale="0.001 0.001 0.001" />
            </geometry>
            <material name="silver" />
        </visual>
        <collision>
            <origin rpy="0 0 0" xyz="-0.026748 -0.148828 0.00381" />
            <geometry>
                <mesh filename="package://hand_urdf_description/meshes/mp4_1.stl" scale="0.001 0.001 0.001" />
            </geometry>
        </collision>
    </link>
    <link name="dp4_1">
        <inertial>
            <origin rpy="0 0 0" xyz="-0.004292693148604226 0.014295947443138057 -0.00024651467227084205" />
            <mass value="0.015173806174410396" />
            <inertia ixx="1e-06" ixy="-0.0" ixz="0.0" iyy="1e-06" iyz="0.0" izz="1e-06" />
        </inertial>
        <visual>
            <origin rpy="0 0 0" xyz="-0.0426 -0.175566 0.004033" />
            <geometry>
                <mesh filename="package://hand_urdf_description/meshes/dp4_1.stl" scale="0.001 0.001 0.001" />
            </geometry>
            <material name="silver" />
        </visual>
        <collision>
            <origin rpy="0 0 0" xyz="-0.0426 -0.175566 0.004033" />
            <geometry>
                <mesh filename="package://hand_urdf_description/meshes/dp4_1.stl" scale="0.001 0.001 0.001" />
            </geometry>
        </collision>
    </link>
    <link name="act1_1">
        <inertial>
            <origin rpy="0 0 0" xyz="-0.0008334783690262457 -0.010584048424232925 0.013540137304842742" />
            <mass value="0.05002702926944018" />
            <inertia ixx="6e-06" ixy="1e-06" ixz="-1e-06" iyy="8e-06" iyz="2e-06" izz="9e-06" />
        </inertial>
        <visual>
            <origin rpy="0 0 0" xyz="0.056571 -0.049357 0.03252" />
            <geometry>
                <mesh filename="package://hand_urdf_description/meshes/act1_1.stl" scale="0.001 0.001 0.001" />
            </geometry>
            <material name="silver" />
        </visual>
        <collision>
            <origin rpy="0 0 0" xyz="0.056571 -0.049357 0.03252" />
            <geometry>
                <mesh filename="package://hand_urdf_description/meshes/act1_1.stl" scale="0.001 0.001 0.001" />
            </geometry>
        </collision>
    </link>
    <link name="act2_1">
        <inertial>
            <origin rpy="0 0 0" xyz="-0.002920339024002166 -0.0093747457460025 0.014129623411935913" />
            <mass value="0.05002702926944018" />
            <inertia ixx="1e-05" ixy="0.0" ixz="0.0" iyy="6e-06" iyz="-0.0" izz="8e-06" />
        </inertial>
        <visual>
            <origin rpy="0 0 0" xyz="0.027409 -0.118436 -0.007531" />
            <geometry>
                <mesh filename="package://hand_urdf_description/meshes/act2_1.stl" scale="0.001 0.001 0.001" />
            </geometry>
            <material name="silver" />
        </visual>
        <collision>
            <origin rpy="0 0 0" xyz="0.027409 -0.118436 -0.007531" />
            <geometry>
                <mesh filename="package://hand_urdf_description/meshes/act2_1.stl" scale="0.001 0.001 0.001" />
            </geometry>
        </collision>
    </link>
    <link name="act3_1">
        <inertial>
            <origin rpy="0 0 0" xyz="-0.003499620624628681 -0.00909927882179469 0.014178076037896649" />
            <mass value="0.05002702926944018" />
            <inertia ixx="1e-05" ixy="0.0" ixz="0.0" iyy="6e-06" iyz="-0.0" izz="8e-06" />
        </inertial>
        <visual>
            <origin rpy="0 0 0" xyz="-0.00395 -0.119269 -0.007678" />
            <geometry>
                <mesh filename="package://hand_urdf_description/meshes/act3_1.stl" scale="0.001 0.001 0.001" />
            </geometry>
            <material name="silver" />
        </visual>
        <collision>
            <origin rpy="0 0 0" xyz="-0.00395 -0.119269 -0.007678" />
            <geometry>
                <mesh filename="package://hand_urdf_description/meshes/act3_1.stl" scale="0.001 0.001 0.001" />
            </geometry>
        </collision>
    </link>
    <link name="act4_1">
        <inertial>
            <origin rpy="0 0 0" xyz="-0.004053505679259262 -0.008773746709272695 0.014235875564707942" />
            <mass value="0.05002702926944018" />
            <inertia ixx="1e-05" ixy="-0.0" ixz="-0.0" iyy="6e-06" iyz="-0.0" izz="8e-06" />
        </inertial>
        <visual>
            <origin rpy="0 0 0" xyz="-0.035164 -0.110753 -0.006176" />
            <geometry>
                <mesh filename="package://hand_urdf_description/meshes/act4_1.stl" scale="0.001 0.001 0.001" />
            </geometry>
            <material name="silver" />
        </visual>
        <collision>
            <origin rpy="0 0 0" xyz="-0.035164 -0.110753 -0.006176" />
            <geometry>
                <mesh filename="package://hand_urdf_description/meshes/act4_1.stl" scale="0.001 0.001 0.001" />
            </geometry>
        </collision>
    </link>
    <joint name="aa2" type="continuous">
        <origin rpy="0 0 0" xyz="-0.014472 0.057309 -0.033152" />
        <parent link="meta2_1" />
        <child link="mcp2_1" />
        <axis xyz="0.0 -0.173648 0.984808" />
    </joint>
    <joint name="mcp2" type="continuous">
        <origin rpy="0 0 0" xyz="-0.008953 0.01468 0.010509" />
        <parent link="mcp2_1" />
        <child link="pp2_1" />
        <axis xyz="-0.996195 -0.085832 -0.015134" />
    </joint>
    <joint name="pip2" type="continuous">
        <origin rpy="0 0 0" xyz="-0.003931 0.039809 -3.3e-05" />
        <parent link="pp2_1" />
        <child link="mp2_1" />
        <axis xyz="-0.996195 -0.085832 -0.015134" />
    </joint>
    <joint name="dip2" type="continuous">
        <origin rpy="0 0 0" xyz="8.7e-05 0.028112 1.9e-05" />
        <parent link="mp2_1" />
        <child link="dp2_1" />
        <axis xyz="-0.996195 -0.085832 -0.015134" />
    </joint>
    <joint name="rigid2" type="fixed">
        <origin rpy="0 0 0" xyz="-0.01455 0.042738 0.019873" />
        <parent link="palm" />
        <child link="meta2_1" />
    </joint>
    <joint name="rigid1" type="fixed">
        <origin rpy="0 0 0" xyz="-0.001495 0.018282 0.014265" />
        <parent link="palm" />
        <child link="meta1_1" />
    </joint>
    <joint name="aa1" type="continuous">
        <origin rpy="0 0 0" xyz="-0.028418 0.038978 -0.047603" />
        <parent link="meta1_1" />
        <child link="mcp1_1" />
        <axis xyz="-0.42367 -0.700575 0.574195" />
    </joint>
    <joint name="mcp1" type="continuous">
        <origin rpy="0 0 0" xyz="-0.018968 0.004511 0.005092" />
        <parent link="mcp1_1" />
        <child link="pp1_1" />
        <axis xyz="0.037066 -0.646775 -0.76178" />
    </joint>
    <joint name="pip1" type="continuous">
        <origin rpy="0 0 0" xyz="-0.032135 0.006716 -0.027613" />
        <parent link="pp1_1" />
        <child link="mp1_1" />
        <axis xyz="0.037066 -0.646775 -0.76178" />
    </joint>
    <joint name="dip1" type="continuous">
        <origin rpy="0 0 0" xyz="-0.023397 0.020451 -0.00078" />
        <parent link="mp1_1" />
        <child link="dp1_1" />
        <axis xyz="0.037066 -0.646775 -0.76178" />
    </joint>
    <joint name="rigid3" type="fixed">
        <origin rpy="0 0 0" xyz="0.01045 0.042738 0.019873" />
        <parent link="palm" />
        <child link="meta3_1" />
    </joint>
    <joint name="aa3" type="continuous">
        <origin rpy="0 0 0" xyz="-0.01 0.058361 -0.032966" />
        <parent link="meta3_1" />
        <child link="mcp3_1" />
        <axis xyz="0.0 -0.173648 0.984808" />
    </joint>
    <joint name="mcp3" type="continuous">
        <origin rpy="0 0 0" xyz="0.0075 0.015388 0.010633" />
        <parent link="mcp3_1" />
        <child link="pp3_1" />
        <axis xyz="-1.0 -0.0 0.0" />
    </joint>
    <joint name="pip3" type="continuous">
        <origin rpy="0 0 0" xyz="-0.0155 0.04 0.0" />
        <parent link="pp3_1" />
        <child link="mp3_1" />
        <axis xyz="-1.0 -0.0 0.0" />
    </joint>
    <joint name="dip3" type="continuous">
        <origin rpy="0 0 0" xyz="0.0135 0.028 0.0" />
        <parent link="mp3_1" />
        <child link="dp3_1" />
        <axis xyz="-1.0 -0.0 -0.0" />
    </joint>
    <joint name="rigid4" type="fixed">
        <origin rpy="0 0 0" xyz="0.035255 0.033939 0.018322" />
        <parent link="palm" />
        <child link="meta4_1" />
    </joint>
    <joint name="aa4" type="continuous">
        <origin rpy="0 0 0" xyz="-0.005452 0.059026 -0.032849" />
        <parent link="meta4_1" />
        <child link="mcp4_1" />
        <axis xyz="0.0 -0.173648 0.984808" />
    </joint>
    <joint name="mcp4" type="continuous">
        <origin rpy="0 0 0" xyz="0.008953 0.01468 0.010508" />
        <parent link="mcp4_1" />
        <child link="pp4_1" />
        <axis xyz="-0.996195 0.085832 0.015134" />
    </joint>
    <joint name="pip4" type="continuous">
        <origin rpy="0 0 0" xyz="-0.012008 0.041183 0.000209" />
        <parent link="pp4_1" />
        <child link="mp4_1" />
        <axis xyz="-1.0 -0.0 0.0" />
    </joint>
    <joint name="dip4" type="continuous">
        <origin rpy="0 0 0" xyz="0.015852 0.026738 -0.000223" />
        <parent link="mp4_1" />
        <child link="dp4_1" />
        <axis xyz="-0.996195 0.085832 0.015134" />
    </joint>
    <joint name="act1" type="continuous">
        <origin rpy="0 0 0" xyz="-0.026658 -0.007903 0.000818" />
        <parent link="mcp1_1" />
        <child link="act1_1" />
        <axis xyz="0.037066 -0.646775 -0.76178" />
    </joint>
    <joint name="act2" type="continuous">
        <origin rpy="0 0 0" xyz="0.001613 0.018389 0.02081" />
        <parent link="mcp2_1" />
        <child link="act2_1" />
        <axis xyz="-0.996195 -0.085832 -0.015134" />
    </joint>
    <joint name="act3" type="continuous">
        <origin rpy="0 0 0" xyz="0.0035 0.01817 0.020771" />
        <parent link="mcp3_1" />
        <child link="act3_1" />
        <axis xyz="-1.0 -0.0 0.0" />
    </joint>
    <joint name="act4" type="continuous">
        <origin rpy="0 0 0" xyz="0.005361 0.017788 0.020703" />
        <parent link="mcp4_1" />
        <child link="act4_1" />
        <axis xyz="-0.996195 0.085832 0.015134" />
    </joint>
    <transmission name="trans_R_HipYaw_Joint">
        <type>transmission_interface/SimpleTransmission</type>
        <joint name="R_HipYaw_Joint">
            <hardwareInterface>hardware_interface/EffortJointInterface</hardwareInterface>
        </joint>
        <actuator name="R_HipYaw_Joint_motor">
            <hardwareInterface>hardware_interface/EffortJointInterface</hardwareInterface>
            <mechanicalReduction>1</mechanicalReduction>
        </actuator>
    </transmission>
    <transmission name="trans_R_HipRoll_Joint">
        <type>transmission_interface/SimpleTransmission</type>
        <joint name="R_HipRoll_Joint">
            <hardwareInterface>hardware_interface/EffortJointInterface</hardwareInterface>
        </joint>
        <actuator name="R_HipRoll_Joint_motor">
            <hardwareInterface>hardware_interface/EffortJointInterface</hardwareInterface>
            <mechanicalReduction>1</mechanicalReduction>
        </actuator>
    </transmission>
    <transmission name="trans_R_HipPitch_Joint">
        <type>transmission_interface/SimpleTransmission</type>
        <joint name="R_HipPitch_Joint">
            <hardwareInterface>hardware_interface/EffortJointInterface</hardwareInterface>
        </joint>
        <actuator name="R_HipPitch_Joint_motor">
            <hardwareInterface>hardware_interface/EffortJointInterface</hardwareInterface>
            <mechanicalReduction>1</mechanicalReduction>
        </actuator>
    </transmission>
    <transmission name="trans_R_Knee_Joint">
        <type>transmission_interface/SimpleTransmission</type>
        <joint name="R_Knee_Joint">
            <hardwareInterface>hardware_interface/EffortJointInterface</hardwareInterface>
        </joint>
        <actuator name="R_Knee_Joint_motor">
            <hardwareInterface>hardware_interface/EffortJointInterface</hardwareInterface>
            <mechanicalReduction>1</mechanicalReduction>
        </actuator>
    </transmission>
    <transmission name="trans_R_AnklePitch_Joint">
        <type>transmission_interface/SimpleTransmission</type>
        <joint name="R_AnklePitch_Joint">
            <hardwareInterface>hardware_interface/EffortJointInterface</hardwareInterface>
        </joint>
        <actuator name="R_AnklePitch_Joint_motor">
            <hardwareInterface>hardware_interface/EffortJointInterface</hardwareInterface>
            <mechanicalReduction>1</mechanicalReduction>
        </actuator>
    </transmission>
    <transmission name="trans_R_AnkleRoll_Joint">
        <type>transmission_interface/SimpleTransmission</type>
        <joint name="R_AnkleRoll_Joint">
            <hardwareInterface>hardware_interface/EffortJointInterface</hardwareInterface>
        </joint>
        <actuator name="R_AnkleRoll_Joint_motor">
            <hardwareInterface>hardware_interface/EffortJointInterface</hardwareInterface>
            <mechanicalReduction>1</mechanicalReduction>
        </actuator>
    </transmission>
    <transmission name="trans_L_HipYaw_Joint">
        <type>transmission_interface/SimpleTransmission</type>
        <joint name="L_HipYaw_Joint">
            <hardwareInterface>hardware_interface/EffortJointInterface</hardwareInterface>
        </joint>
        <actuator name="L_HipYaw_Joint_motor">
            <hardwareInterface>hardware_interface/EffortJointInterface</hardwareInterface>
            <mechanicalReduction>1</mechanicalReduction>
        </actuator>
    </transmission>
    <transmission name="trans_L_HipRoll_Joint">
        <type>transmission_interface/SimpleTransmission</type>
        <joint name="L_HipRoll_Joint">
            <hardwareInterface>hardware_interface/EffortJointInterface</hardwareInterface>
        </joint>
        <actuator name="L_HipRoll_Joint_motor">
            <hardwareInterface>hardware_interface/EffortJointInterface</hardwareInterface>
            <mechanicalReduction>1</mechanicalReduction>
        </actuator>
    </transmission>
    <transmission name="trans_L_HipPitch_Joint">
        <type>transmission_interface/SimpleTransmission</type>
        <joint name="L_HipPitch_Joint">
            <hardwareInterface>hardware_interface/EffortJointInterface</hardwareInterface>
        </joint>
        <actuator name="L_HipPitch_Joint_motor">
            <hardwareInterface>hardware_interface/EffortJointInterface</hardwareInterface>
            <mechanicalReduction>1</mechanicalReduction>
        </actuator>
    </transmission>
    <transmission name="trans_L_Knee_Joint">
        <type>transmission_interface/SimpleTransmission</type>
        <joint name="L_Knee_Joint">
            <hardwareInterface>hardware_interface/EffortJointInterface</hardwareInterface>
        </joint>
        <actuator name="L_Knee_Joint_motor">
            <hardwareInterface>hardware_interface/EffortJointInterface</hardwareInterface>
            <mechanicalReduction>1</mechanicalReduction>
        </actuator>
    </transmission>
    <transmission name="trans_L_AnklePitch_Joint">
        <type>transmission_interface/SimpleTransmission</type>
        <joint name="L_AnklePitch_Joint">
            <hardwareInterface>hardware_interface/EffortJointInterface</hardwareInterface>
        </joint>
        <actuator name="L_AnklePitch_Joint_motor">
            <hardwareInterface>hardware_interface/EffortJointInterface</hardwareInterface>
            <mechanicalReduction>1</mechanicalReduction>
        </actuator>
    </transmission>
    <transmission name="trans_L_AnkleRoll_Joint">
        <type>transmission_interface/SimpleTransmission</type>
        <joint name="L_AnkleRoll_Joint">
            <hardwareInterface>hardware_interface/EffortJointInterface</hardwareInterface>
        </joint>
        <actuator name="L_AnkleRoll_Joint_motor">
            <hardwareInterface>hardware_interface/EffortJointInterface</hardwareInterface>
            <mechanicalReduction>1</mechanicalReduction>
        </actuator>
    </transmission>
    <transmission name="trans_Waist1_Joint">
        <type>transmission_interface/SimpleTransmission</type>
        <joint name="Waist1_Joint">
            <hardwareInterface>hardware_interface/EffortJointInterface</hardwareInterface>
        </joint>
        <actuator name="Waist1_Joint_motor">
            <hardwareInterface>hardware_interface/EffortJointInterface</hardwareInterface>
            <mechanicalReduction>1</mechanicalReduction>
        </actuator>
    </transmission>
    <transmission name="trans_Waist2_Joint">
        <type>transmission_interface/SimpleTransmission</type>
        <joint name="Waist2_Joint">
            <hardwareInterface>hardware_interface/EffortJointInterface</hardwareInterface>
        </joint>
        <actuator name="Waist2_Joint_motor">
            <hardwareInterface>hardware_interface/EffortJointInterface</hardwareInterface>
            <mechanicalReduction>1</mechanicalReduction>
        </actuator>
    </transmission>
    <transmission name="trans_Upperbody_Joint">
        <type>transmission_interface/SimpleTransmission</type>
        <joint name="Upperbody_Joint">
            <hardwareInterface>hardware_interface/EffortJointInterface</hardwareInterface>
        </joint>
        <actuator name="Upperbody_Joint_motor">
            <hardwareInterface>hardware_interface/EffortJointInterface</hardwareInterface>
            <mechanicalReduction>1</mechanicalReduction>
        </actuator>
    </transmission>
    <transmission name="trans_Neck_Joint">
        <type>transmission_interface/SimpleTransmission</type>
        <joint name="Neck_Joint">
            <hardwareInterface>hardware_interface/EffortJointInterface</hardwareInterface>
        </joint>
        <actuator name="Neck_Joint_motor">
            <hardwareInterface>hardware_interface/EffortJointInterface</hardwareInterface>
            <mechanicalReduction>1</mechanicalReduction>
        </actuator>
    </transmission>
    <transmission name="trans_Head_Joint">
        <type>transmission_interface/SimpleTransmission</type>
        <joint name="Head_Joint">
            <hardwareInterface>hardware_interface/EffortJointInterface</hardwareInterface>
        </joint>
        <actuator name="Head_Joint_motor">
            <hardwareInterface>hardware_interface/EffortJointInterface</hardwareInterface>
            <mechanicalReduction>1</mechanicalReduction>
        </actuator>
    </transmission>
    <transmission name="trans_L_Shoulder1_Joint">
        <type>transmission_interface/SimpleTransmission</type>
        <joint name="L_Shoulder1_Joint">
            <hardwareInterface>hardware_interface/EffortJointInterface</hardwareInterface>
        </joint>
        <actuator name="L_Shoulder1_Joint_motor">
            <hardwareInterface>hardware_interface/EffortJointInterface</hardwareInterface>
            <mechanicalReduction>1</mechanicalReduction>
        </actuator>
    </transmission>
    <transmission name="trans_L_Shoulder2_Joint">
        <type>transmission_interface/SimpleTransmission</type>
        <joint name="L_Shoulder2_Joint">
            <hardwareInterface>hardware_interface/EffortJointInterface</hardwareInterface>
        </joint>
        <actuator name="L_Shoulder2_Joint_motor">
            <hardwareInterface>hardware_interface/EffortJointInterface</hardwareInterface>
            <mechanicalReduction>1</mechanicalReduction>
        </actuator>
    </transmission>
    <transmission name="trans_L_Shoulder3_Joint">
        <type>transmission_interface/SimpleTransmission</type>
        <joint name="L_Shoulder3_Joint">
            <hardwareInterface>hardware_interface/EffortJointInterface</hardwareInterface>
        </joint>
        <actuator name="L_Shoulder3_Joint_motor">
            <hardwareInterface>hardware_interface/EffortJointInterface</hardwareInterface>
            <mechanicalReduction>1</mechanicalReduction>
        </actuator>
    </transmission>
    <transmission name="trans_L_Armlink_Joint">
        <type>transmission_interface/SimpleTransmission</type>
        <joint name="L_Armlink_Joint">
            <hardwareInterface>hardware_interface/EffortJointInterface</hardwareInterface>
        </joint>
        <actuator name="L_Armlink_Joint_motor">
            <hardwareInterface>hardware_interface/EffortJointInterface</hardwareInterface>
            <mechanicalReduction>1</mechanicalReduction>
        </actuator>
    </transmission>
    <transmission name="trans_L_Elbow_Joint">
        <type>transmission_interface/SimpleTransmission</type>
        <joint name="L_Elbow_Joint">
            <hardwareInterface>hardware_interface/EffortJointInterface</hardwareInterface>
        </joint>
        <actuator name="L_Elbow_Joint_motor">
            <hardwareInterface>hardware_interface/EffortJointInterface</hardwareInterface>
            <mechanicalReduction>1</mechanicalReduction>
        </actuator>
    </transmission>
    <transmission name="trans_L_Forearm_Joint">
        <type>transmission_interface/SimpleTransmission</type>
        <joint name="L_Forearm_Joint">
            <hardwareInterface>hardware_interface/EffortJointInterface</hardwareInterface>
        </joint>
        <actuator name="L_Forearm_Joint_motor">
            <hardwareInterface>hardware_interface/EffortJointInterface</hardwareInterface>
            <mechanicalReduction>1</mechanicalReduction>
        </actuator>
    </transmission>
    <transmission name="trans_L_Wrist1_Joint">
        <type>transmission_interface/SimpleTransmission</type>
        <joint name="L_Wrist1_Joint">
            <hardwareInterface>hardware_interface/EffortJointInterface</hardwareInterface>
        </joint>
        <actuator name="L_Wrist1_Joint_motor">
            <hardwareInterface>hardware_interface/EffortJointInterface</hardwareInterface>
            <mechanicalReduction>1</mechanicalReduction>
        </actuator>
    </transmission>
    <transmission name="trans_L_Wrist2_Joint">
        <type>transmission_interface/SimpleTransmission</type>
        <joint name="L_Wrist2_Joint">
            <hardwareInterface>hardware_interface/EffortJointInterface</hardwareInterface>
        </joint>
        <actuator name="L_Wrist2_Joint_motor">
            <hardwareInterface>hardware_interface/EffortJointInterface</hardwareInterface>
            <mechanicalReduction>1</mechanicalReduction>
        </actuator>
    </transmission>
    <transmission name="trans_R_Shoulder1_Joint">
        <type>transmission_interface/SimpleTransmission</type>
        <joint name="R_Shoulder1_Joint">
            <hardwareInterface>hardware_interface/EffortJointInterface</hardwareInterface>
        </joint>
        <actuator name="R_Shoulder1_Joint_motor">
            <hardwareInterface>hardware_interface/EffortJointInterface</hardwareInterface>
            <mechanicalReduction>1</mechanicalReduction>
        </actuator>
    </transmission>
    <transmission name="trans_R_Shoulder2_Joint">
        <type>transmission_interface/SimpleTransmission</type>
        <joint name="R_Shoulder2_Joint">
            <hardwareInterface>hardware_interface/EffortJointInterface</hardwareInterface>
        </joint>
        <actuator name="R_Shoulder2_Joint_motor">
            <hardwareInterface>hardware_interface/EffortJointInterface</hardwareInterface>
            <mechanicalReduction>1</mechanicalReduction>
        </actuator>
    </transmission>
    <transmission name="trans_R_Shoulder3_Joint">
        <type>transmission_interface/SimpleTransmission</type>
        <joint name="R_Shoulder3_Joint">
            <hardwareInterface>hardware_interface/EffortJointInterface</hardwareInterface>
        </joint>
        <actuator name="R_Shoulder3_Joint_motor">
            <hardwareInterface>hardware_interface/EffortJointInterface</hardwareInterface>
            <mechanicalReduction>1</mechanicalReduction>
        </actuator>
    </transmission>
    <transmission name="trans_R_Armlink_Joint">
        <type>transmission_interface/SimpleTransmission</type>
        <joint name="R_Armlink_Joint">
            <hardwareInterface>hardware_interface/EffortJointInterface</hardwareInterface>
        </joint>
        <actuator name="R_Armlink_Joint_motor">
            <hardwareInterface>hardware_interface/EffortJointInterface</hardwareInterface>
            <mechanicalReduction>1</mechanicalReduction>
        </actuator>
    </transmission>
    <transmission name="trans_R_Elbow_Joint">
        <type>transmission_interface/SimpleTransmission</type>
        <joint name="R_Elbow_Joint">
            <hardwareInterface>hardware_interface/EffortJointInterface</hardwareInterface>
        </joint>
        <actuator name="R_Elbow_Joint_motor">
            <hardwareInterface>hardware_interface/EffortJointInterface</hardwareInterface>
            <mechanicalReduction>1</mechanicalReduction>
        </actuator>
    </transmission>
    <transmission name="trans_R_Forearm_Joint">
        <type>transmission_interface/SimpleTransmission</type>
        <joint name="R_Forearm_Joint">
            <hardwareInterface>hardware_interface/EffortJointInterface</hardwareInterface>
        </joint>
        <actuator name="R_Forearm_Joint_motor">
            <hardwareInterface>hardware_interface/EffortJointInterface</hardwareInterface>
            <mechanicalReduction>1</mechanicalReduction>
        </actuator>
    </transmission>
    <transmission name="trans_R_Wrist1_Joint">
        <type>transmission_interface/SimpleTransmission</type>
        <joint name="R_Wrist1_Joint">
            <hardwareInterface>hardware_interface/EffortJointInterface</hardwareInterface>
        </joint>
        <actuator name="R_Wrist1_Joint_motor">
            <hardwareInterface>hardware_interface/EffortJointInterface</hardwareInterface>
            <mechanicalReduction>1</mechanicalReduction>
        </actuator>
    </transmission>
    <transmission name="trans_R_Wrist2_Joint">
        <type>transmission_interface/SimpleTransmission</type>
        <joint name="R_Wrist2_Joint">
            <hardwareInterface>hardware_interface/EffortJointInterface</hardwareInterface>
        </joint>
        <actuator name="R_Wrist2_Joint_motor">
            <hardwareInterface>hardware_interface/EffortJointInterface</hardwareInterface>
            <mechanicalReduction>1</mechanicalReduction>
        </actuator>
    </transmission>
    <transmission name="trans_aa2">
        <type>transmission_interface/SimpleTransmission</type>
        <joint name="aa2">
            <hardwareInterface>hardware_interface/EffortJointInterface</hardwareInterface>
        </joint>
        <actuator name="aa2_motor">
            <hardwareInterface>hardware_interface/EffortJointInterface</hardwareInterface>
            <mechanicalReduction>1</mechanicalReduction>
        </actuator>
    </transmission>
    <transmission name="trans_mcp2">
        <type>transmission_interface/SimpleTransmission</type>
        <joint name="mcp2">
            <hardwareInterface>hardware_interface/EffortJointInterface</hardwareInterface>
        </joint>
        <actuator name="mcp2_motor">
            <hardwareInterface>hardware_interface/EffortJointInterface</hardwareInterface>
            <mechanicalReduction>1</mechanicalReduction>
        </actuator>
    </transmission>
    <transmission name="trans_pip2">
        <type>transmission_interface/SimpleTransmission</type>
        <joint name="pip2">
            <hardwareInterface>hardware_interface/EffortJointInterface</hardwareInterface>
        </joint>
        <actuator name="pip2_motor">
            <hardwareInterface>hardware_interface/EffortJointInterface</hardwareInterface>
            <mechanicalReduction>1</mechanicalReduction>
        </actuator>
    </transmission>
    <transmission name="trans_dip2">
        <type>transmission_interface/SimpleTransmission</type>
        <joint name="dip2">
            <hardwareInterface>hardware_interface/EffortJointInterface</hardwareInterface>
        </joint>
        <actuator name="dip2_motor">
            <hardwareInterface>hardware_interface/EffortJointInterface</hardwareInterface>
            <mechanicalReduction>1</mechanicalReduction>
        </actuator>
    </transmission>
    <transmission name="trans_aa1">
        <type>transmission_interface/SimpleTransmission</type>
        <joint name="aa1">
            <hardwareInterface>hardware_interface/EffortJointInterface</hardwareInterface>
        </joint>
        <actuator name="aa1_motor">
            <hardwareInterface>hardware_interface/EffortJointInterface</hardwareInterface>
            <mechanicalReduction>1</mechanicalReduction>
        </actuator>
    </transmission>
    <transmission name="trans_mcp1">
        <type>transmission_interface/SimpleTransmission</type>
        <joint name="mcp1">
            <hardwareInterface>hardware_interface/EffortJointInterface</hardwareInterface>
        </joint>
        <actuator name="mcp1_motor">
            <hardwareInterface>hardware_interface/EffortJointInterface</hardwareInterface>
            <mechanicalReduction>1</mechanicalReduction>
        </actuator>
    </transmission>
    <transmission name="trans_pip1">
        <type>transmission_interface/SimpleTransmission</type>
        <joint name="pip1">
            <hardwareInterface>hardware_interface/EffortJointInterface</hardwareInterface>
        </joint>
        <actuator name="pip1_motor">
            <hardwareInterface>hardware_interface/EffortJointInterface</hardwareInterface>
            <mechanicalReduction>1</mechanicalReduction>
        </actuator>
    </transmission>
    <transmission name="trans_dip1">
        <type>transmission_interface/SimpleTransmission</type>
        <joint name="dip1">
            <hardwareInterface>hardware_interface/EffortJointInterface</hardwareInterface>
        </joint>
        <actuator name="dip1_motor">
            <hardwareInterface>hardware_interface/EffortJointInterface</hardwareInterface>
            <mechanicalReduction>1</mechanicalReduction>
        </actuator>
    </transmission>
    <transmission name="trans_aa3">
        <type>transmission_interface/SimpleTransmission</type>
        <joint name="aa3">
            <hardwareInterface>hardware_interface/EffortJointInterface</hardwareInterface>
        </joint>
        <actuator name="aa3_motor">
            <hardwareInterface>hardware_interface/EffortJointInterface</hardwareInterface>
            <mechanicalReduction>1</mechanicalReduction>
        </actuator>
    </transmission>
    <transmission name="trans_mcp3">
        <type>transmission_interface/SimpleTransmission</type>
        <joint name="mcp3">
            <hardwareInterface>hardware_interface/EffortJointInterface</hardwareInterface>
        </joint>
        <actuator name="mcp3_motor">
            <hardwareInterface>hardware_interface/EffortJointInterface</hardwareInterface>
            <mechanicalReduction>1</mechanicalReduction>
        </actuator>
    </transmission>
    <transmission name="trans_pip3">
        <type>transmission_interface/SimpleTransmission</type>
        <joint name="pip3">
            <hardwareInterface>hardware_interface/EffortJointInterface</hardwareInterface>
        </joint>
        <actuator name="pip3_motor">
            <hardwareInterface>hardware_interface/EffortJointInterface</hardwareInterface>
            <mechanicalReduction>1</mechanicalReduction>
        </actuator>
    </transmission>
    <transmission name="trans_dip3">
        <type>transmission_interface/SimpleTransmission</type>
        <joint name="dip3">
            <hardwareInterface>hardware_interface/EffortJointInterface</hardwareInterface>
        </joint>
        <actuator name="dip3_motor">
            <hardwareInterface>hardware_interface/EffortJointInterface</hardwareInterface>
            <mechanicalReduction>1</mechanicalReduction>
        </actuator>
    </transmission>
    <transmission name="trans_aa4">
        <type>transmission_interface/SimpleTransmission</type>
        <joint name="aa4">
            <hardwareInterface>hardware_interface/EffortJointInterface</hardwareInterface>
        </joint>
        <actuator name="aa4_motor">
            <hardwareInterface>hardware_interface/EffortJointInterface</hardwareInterface>
            <mechanicalReduction>1</mechanicalReduction>
        </actuator>
    </transmission>
    <transmission name="trans_mcp4">
        <type>transmission_interface/SimpleTransmission</type>
        <joint name="mcp4">
            <hardwareInterface>hardware_interface/EffortJointInterface</hardwareInterface>
        </joint>
        <actuator name="mcp4_motor">
            <hardwareInterface>hardware_interface/EffortJointInterface</hardwareInterface>
            <mechanicalReduction>1</mechanicalReduction>
        </actuator>
    </transmission>
    <transmission name="trans_pip4">
        <type>transmission_interface/SimpleTransmission</type>
        <joint name="pip4">
            <hardwareInterface>hardware_interface/EffortJointInterface</hardwareInterface>
        </joint>
        <actuator name="pip4_motor">
            <hardwareInterface>hardware_interface/EffortJointInterface</hardwareInterface>
            <mechanicalReduction>1</mechanicalReduction>
        </actuator>
    </transmission>
    <transmission name="trans_dip4">
        <type>transmission_interface/SimpleTransmission</type>
        <joint name="dip4">
            <hardwareInterface>hardware_interface/EffortJointInterface</hardwareInterface>
        </joint>
        <actuator name="dip4_motor">
            <hardwareInterface>hardware_interface/EffortJointInterface</hardwareInterface>
            <mechanicalReduction>1</mechanicalReduction>
        </actuator>
    </transmission>
    <transmission name="trans_act1">
        <type>transmission_interface/SimpleTransmission</type>
        <joint name="act1">
            <hardwareInterface>hardware_interface/EffortJointInterface</hardwareInterface>
        </joint>
        <actuator name="act1_motor">
            <hardwareInterface>hardware_interface/EffortJointInterface</hardwareInterface>
            <mechanicalReduction>1</mechanicalReduction>
        </actuator>
    </transmission>
    <transmission name="trans_act2">
        <type>transmission_interface/SimpleTransmission</type>
        <joint name="act2">
            <hardwareInterface>hardware_interface/EffortJointInterface</hardwareInterface>
        </joint>
        <actuator name="act2_motor">
            <hardwareInterface>hardware_interface/EffortJointInterface</hardwareInterface>
            <mechanicalReduction>1</mechanicalReduction>
        </actuator>
    </transmission>
    <transmission name="trans_act3">
        <type>transmission_interface/SimpleTransmission</type>
        <joint name="act3">
            <hardwareInterface>hardware_interface/EffortJointInterface</hardwareInterface>
        </joint>
        <actuator name="act3_motor">
            <hardwareInterface>hardware_interface/EffortJointInterface</hardwareInterface>
            <mechanicalReduction>1</mechanicalReduction>
        </actuator>
    </transmission>
    <transmission name="trans_act4">
        <type>transmission_interface/SimpleTransmission</type>
        <joint name="act4">
            <hardwareInterface>hardware_interface/EffortJointInterface</hardwareInterface>
        </joint>
        <actuator name="act4_motor">
            <hardwareInterface>hardware_interface/EffortJointInterface</hardwareInterface>
            <mechanicalReduction>1</mechanicalReduction>
        </actuator>
    </transmission>
    <gazebo>
        <plugin name="gazebo_ros_control">
            <robotNamespace>/</robotNamespace>
        </plugin>
    </gazebo>
</robot>

